Workbook

Sheet 新バージョンについて
A1: 車いす乗車表新Verについて
A3: ・表示の行数は下記のとおりです。
B4: 三食 | C4: 昼のみ | D4: 夜のみ | E4: AM | F4: PM | G4: 印刷について
A5: 旧乗車表 | B5: 8 | C5: 8 | D5: なし | E5: 4 | F5: 12 | G5: A4両面×２枚
A6: 新A4乗車表 | B6: 12 | C6: 8 | D6: 3 | E6: 8 | F6: 15 | G6: A4両面×２枚
A7: 新A3乗車表 | B7: 12 | C7: 8 | D7: 3 | E7: 8 | F7: 15 | G7: A3両面×１枚
A8: ※新旧すべてのverは報告用を編集するとすべて同時に作成されます。
A11: ・行数が増えた関係で表示が小さくなり見辛くなったかもしれないため、Ａ４サイズとＡ３サイズを作りました。
A12: ・Ａ３が大きすぎる場合はＡ３版をＢ４に縮小印刷するとよいかもしれません。
A13: ・病棟で使用感の良いほうを検討してください。
A17: ・夜のみが新設されました。昼・夜食事離床の方がいた場合、昼１行、夜１行用意すれば反映されます。
A20: このシートは見たら削除してもらって構いません。

Sheet 緊急手入力用
G1: Aグループ
A2: ★は土日も三食離床 | M2: =報告用!$O$2 -> 46106
A3: 離床 | B3: 月～金 | G3: 離床 | H3: 月 | M3: 離床 | N3: 火
B4: 部屋 | C4: 氏名 | E4: 車庫 | H4: 部屋 | I4: 氏名 | K4: 車庫 | N4: 部屋 | O4: 氏名 | Q4: 車庫
A5: 三食 | B5: =_xlfn.XLOOKUP(ROW(B5)-ROW(B$4),報告用!$AC$4:$AC$39,報告用!F$4:F$39,"",FALSE) -> 18 | C5: =_xlfn.XLOOKUP(ROW(C5)-ROW(C$4),報告用!$AC$4:$AC$39,報告用!G$4:G$39,"",FALSE) -> 吉井 用子 | D5: =IF(C5="","","様") -> 様 | E5: =IF(_xlfn.XLOOKUP(ROW(E5)-ROW(E$4),報告用!$AC$4:$AC$39,報告用!E$4:E$39,"",FALSE)=B5,"",_xlfn.XLOOKUP(ROW(E5)-ROW(E$4),報告用!$AC$4:$AC$39,報告用!E$4:E$39,"",FALSE)) | G5: AM | H5: =_xlfn.XLOOKUP(ROW(H5)-ROW(H$4),報告用!$AF$4:$AF$39,報告用!$F$4:$F$39,"",FALSE) -> 15 | I5: =_xlfn.XLOOKUP(ROW(I5)-ROW(I$4),報告用!$AF$4:$AF$39,報告用!$G$4:$G$39,"",FALSE) -> 志村とも子 | J5: =IF(I5="","","様") -> 様 | K5: =IF(_xlfn.XLOOKUP(ROW(K5)-ROW(K$4),報告用!$AF$4:$AF$39,報告用!$E$4:$E$39,"",FALSE)=H5,"",_xlfn.XLOOKUP(ROW(K5)-ROW(K$4),報告用!$AF$4:$AF$39,報告用!$E$4:$E$39,"",FALSE)) | M5: AM | N5: =_xlfn.XLOOKUP(ROW(N5)-ROW(N$4),報告用!$AG$4:$AG$39,報告用!$F$4:$F$39,"",FALSE) -> 15 | O5: =_xlfn.XLOOKUP(ROW(O5)-ROW(O$4),報告用!$AG$4:$AG$39,報告用!$G$4:$G$39,"",FALSE) -> 志村とも子 | P5: =IF(O5="","","様") -> 様 | Q5: =IF(_xlfn.XLOOKUP(ROW(Q5)-ROW(Q$4),報告用!$AG$4:$AG$39,報告用!$E$4:$E$39,"",FALSE)=N5,"",_xlfn.XLOOKUP(ROW(Q5)-ROW(Q$4),報告用!$AG$4:$AG$39,報告用!$E$4:$E$39,"",FALSE))
B6: =_xlfn.XLOOKUP(ROW(B6)-ROW(B$4),報告用!$AC$4:$AC$39,報告用!F$4:F$39,"",FALSE) -> 20 | C6: =_xlfn.XLOOKUP(ROW(C6)-ROW(C$4),報告用!$AC$4:$AC$39,報告用!G$4:G$39,"",FALSE) -> ★上條 礼子 | D6: =IF(C6="","","様") -> 様 | E6: =IF(_xlfn.XLOOKUP(ROW(E6)-ROW(E$4),報告用!$AC$4:$AC$39,報告用!E$4:E$39,"",FALSE)=B6,"",_xlfn.XLOOKUP(ROW(E6)-ROW(E$4),報告用!$AC$4:$AC$39,報告用!E$4:E$39,"",FALSE)) | H6: =_xlfn.XLOOKUP(ROW(H6)-ROW(H$4),報告用!$AF$4:$AF$39,報告用!$F$4:$F$39,"",FALSE) -> 15 | I6: =_xlfn.XLOOKUP(ROW(I6)-ROW(I$4),報告用!$AF$4:$AF$39,報告用!$G$4:$G$39,"",FALSE) -> 飯室 純江 | J6: =IF(I6="","","様") -> 様 | K6: =IF(_xlfn.XLOOKUP(ROW(K6)-ROW(K$4),報告用!$AF$4:$AF$39,報告用!$E$4:$E$39,"",FALSE)=H6,"",_xlfn.XLOOKUP(ROW(K6)-ROW(K$4),報告用!$AF$4:$AF$39,報告用!$E$4:$E$39,"",FALSE)) | N6: =_xlfn.XLOOKUP(ROW(N6)-ROW(N$4),報告用!$AG$4:$AG$39,報告用!$F$4:$F$39,"",FALSE) -> 15 | O6: =_xlfn.XLOOKUP(ROW(O6)-ROW(O$4),報告用!$AG$4:$AG$39,報告用!$G$4:$G$39,"",FALSE) -> 望月 美希 | P6: =IF(O6="","","様") -> 様 | Q6: =IF(_xlfn.XLOOKUP(ROW(Q6)-ROW(Q$4),報告用!$AG$4:$AG$39,報告用!$E$4:$E$39,"",FALSE)=N6,"",_xlfn.XLOOKUP(ROW(Q6)-ROW(Q$4),報告用!$AG$4:$AG$39,報告用!$E$4:$E$39,"",FALSE))
B7: =_xlfn.XLOOKUP(ROW(B7)-ROW(B$4),報告用!$AC$4:$AC$39,報告用!F$4:F$39,"",FALSE) | C7: =_xlfn.XLOOKUP(ROW(C7)-ROW(C$4),報告用!$AC$4:$AC$39,報告用!G$4:G$39,"",FALSE) | D7: =IF(C7="","","様") | E7: =IF(_xlfn.XLOOKUP(ROW(E7)-ROW(E$4),報告用!$AC$4:$AC$39,報告用!E$4:E$39,"",FALSE)=B7,"",_xlfn.XLOOKUP(ROW(E7)-ROW(E$4),報告用!$AC$4:$AC$39,報告用!E$4:E$39,"",FALSE)) | H7: =_xlfn.XLOOKUP(ROW(H7)-ROW(H$4),報告用!$AF$4:$AF$39,報告用!$F$4:$F$39,"",FALSE) -> 16 | I7: =_xlfn.XLOOKUP(ROW(I7)-ROW(I$4),報告用!$AF$4:$AF$39,報告用!$G$4:$G$39,"",FALSE) -> 里吉 松子 | J7: =IF(I7="","","様") -> 様 | K7: =IF(_xlfn.XLOOKUP(ROW(K7)-ROW(K$4),報告用!$AF$4:$AF$39,報告用!$E$4:$E$39,"",FALSE)=H7,"",_xlfn.XLOOKUP(ROW(K7)-ROW(K$4),報告用!$AF$4:$AF$39,報告用!$E$4:$E$39,"",FALSE)) | N7: =_xlfn.XLOOKUP(ROW(N7)-ROW(N$4),報告用!$AG$4:$AG$39,報告用!$F$4:$F$39,"",FALSE) -> 16 | O7: =_xlfn.XLOOKUP(ROW(O7)-ROW(O$4),報告用!$AG$4:$AG$39,報告用!$G$4:$G$39,"",FALSE) -> 里吉 松子 | P7: =IF(O7="","","様") -> 様 | Q7: =IF(_xlfn.XLOOKUP(ROW(Q7)-ROW(Q$4),報告用!$AG$4:$AG$39,報告用!$E$4:$E$39,"",FALSE)=N7,"",_xlfn.XLOOKUP(ROW(Q7)-ROW(Q$4),報告用!$AG$4:$AG$39,報告用!$E$4:$E$39,"",FALSE))
B8: =_xlfn.XLOOKUP(ROW(B8)-ROW(B$4),報告用!$AC$4:$AC$39,報告用!F$4:F$39,"",FALSE) | C8: =_xlfn.XLOOKUP(ROW(C8)-ROW(C$4),報告用!$AC$4:$AC$39,報告用!G$4:G$39,"",FALSE) | D8: =IF(C8="","","様") | E8: =IF(_xlfn.XLOOKUP(ROW(E8)-ROW(E$4),報告用!$AC$4:$AC$39,報告用!E$4:E$39,"",FALSE)=B8,"",_xlfn.XLOOKUP(ROW(E8)-ROW(E$4),報告用!$AC$4:$AC$39,報告用!E$4:E$39,"",FALSE)) | H8: =_xlfn.XLOOKUP(ROW(H8)-ROW(H$4),報告用!$AF$4:$AF$39,報告用!$F$4:$F$39,"",FALSE) -> 16 | I8: =_xlfn.XLOOKUP(ROW(I8)-ROW(I$4),報告用!$AF$4:$AF$39,報告用!$G$4:$G$39,"",FALSE) -> 森 たい子 | J8: =IF(I8="","","様") -> 様 | K8: =IF(_xlfn.XLOOKUP(ROW(K8)-ROW(K$4),報告用!$AF$4:$AF$39,報告用!$E$4:$E$39,"",FALSE)=H8,"",_xlfn.XLOOKUP(ROW(K8)-ROW(K$4),報告用!$AF$4:$AF$39,報告用!$E$4:$E$39,"",FALSE)) | N8: =_xlfn.XLOOKUP(ROW(N8)-ROW(N$4),報告用!$AG$4:$AG$39,報告用!$F$4:$F$39,"",FALSE) -> 16 | O8: =_xlfn.XLOOKUP(ROW(O8)-ROW(O$4),報告用!$AG$4:$AG$39,報告用!$G$4:$G$39,"",FALSE) -> 森 たい子 | P8: =IF(O8="","","様") -> 様 | Q8: =IF(_xlfn.XLOOKUP(ROW(Q8)-ROW(Q$4),報告用!$AG$4:$AG$39,報告用!$E$4:$E$39,"",FALSE)=N8,"",_xlfn.XLOOKUP(ROW(Q8)-ROW(Q$4),報告用!$AG$4:$AG$39,報告用!$E$4:$E$39,"",FALSE))
B9: =_xlfn.XLOOKUP(ROW(B9)-ROW(B$4),報告用!$AC$4:$AC$39,報告用!F$4:F$39,"",FALSE) | C9: =_xlfn.XLOOKUP(ROW(C9)-ROW(C$4),報告用!$AC$4:$AC$39,報告用!G$4:G$39,"",FALSE) | D9: =IF(C9="","","様") | E9: =IF(_xlfn.XLOOKUP(ROW(E9)-ROW(E$4),報告用!$AC$4:$AC$39,報告用!E$4:E$39,"",FALSE)=B9,"",_xlfn.XLOOKUP(ROW(E9)-ROW(E$4),報告用!$AC$4:$AC$39,報告用!E$4:E$39,"",FALSE)) | G9: PM | H9: =_xlfn.XLOOKUP(ROW(H9)-ROW(H$8),報告用!$AK$4:$AK$39,報告用!$F$4:$F$39,"",FALSE) -> 15 | I9: =_xlfn.XLOOKUP(ROW(I9)-ROW(I$8),報告用!$AK$4:$AK$39,報告用!$G$4:$G$39,"",FALSE) -> 志村とも子 | J9: =IF(I9="","","様") -> 様 | K9: =IF(_xlfn.XLOOKUP(ROW(K9)-ROW(K$8),報告用!$AK$4:$AK$39,報告用!$E$4:$E$39,"",FALSE)=H9,"",_xlfn.XLOOKUP(ROW(K9)-ROW(K$8),報告用!$AK$4:$AK$39,報告用!$E$4:$E$39,"",FALSE)) | M9: PM | N9: =_xlfn.XLOOKUP(ROW(N9)-ROW(N$8),報告用!$AL$4:$AL$39,報告用!$F$4:$F$39,"",FALSE) -> 15 | O9: =_xlfn.XLOOKUP(ROW(O9)-ROW(O$8),報告用!$AL$4:$AL$39,報告用!$G$4:$G$39,"",FALSE) -> 志村とも子 | P9: =IF(O9="","","様") -> 様 | Q9: =IF(_xlfn.XLOOKUP(ROW(Q9)-ROW(Q$8),報告用!$AL$4:$AL$39,報告用!$E$4:$E$39,"",FALSE)=N9,"",_xlfn.XLOOKUP(ROW(Q9)-ROW(Q$8),報告用!$AL$4:$AL$39,報告用!$E$4:$E$39,"",FALSE))
B10: =_xlfn.XLOOKUP(ROW(B10)-ROW(B$4),報告用!$AC$4:$AC$39,報告用!F$4:F$39,"",FALSE) | C10: =_xlfn.XLOOKUP(ROW(C10)-ROW(C$4),報告用!$AC$4:$AC$39,報告用!G$4:G$39,"",FALSE) | D10: =IF(C10="","","様") | E10: =IF(_xlfn.XLOOKUP(ROW(E10)-ROW(E$4),報告用!$AC$4:$AC$39,報告用!E$4:E$39,"",FALSE)=B10,"",_xlfn.XLOOKUP(ROW(E10)-ROW(E$4),報告用!$AC$4:$AC$39,報告用!E$4:E$39,"",FALSE)) | H10: =_xlfn.XLOOKUP(ROW(H10)-ROW(H$8),報告用!$AK$4:$AK$39,報告用!$F$4:$F$39,"",FALSE) -> 15 | I10: =_xlfn.XLOOKUP(ROW(I10)-ROW(I$8),報告用!$AK$4:$AK$39,報告用!$G$4:$G$39,"",FALSE) -> 佐藤 亜美 | J10: =IF(I10="","","様") -> 様 | K10: =IF(_xlfn.XLOOKUP(ROW(K10)-ROW(K$8),報告用!$AK$4:$AK$39,報告用!$E$4:$E$39,"",FALSE)=H10,"",_xlfn.XLOOKUP(ROW(K10)-ROW(K$8),報告用!$AK$4:$AK$39,報告用!$E$4:$E$39,"",FALSE)) | N10: =_xlfn.XLOOKUP(ROW(N10)-ROW(N$8),報告用!$AL$4:$AL$39,報告用!$F$4:$F$39,"",FALSE) -> 15 | O10: =_xlfn.XLOOKUP(ROW(O10)-ROW(O$8),報告用!$AL$4:$AL$39,報告用!$G$4:$G$39,"",FALSE) -> 佐藤 亜美 | P10: =IF(O10="","","様") -> 様 | Q10: =IF(_xlfn.XLOOKUP(ROW(Q10)-ROW(Q$8),報告用!$AL$4:$AL$39,報告用!$E$4:$E$39,"",FALSE)=N10,"",_xlfn.XLOOKUP(ROW(Q10)-ROW(Q$8),報告用!$AL$4:$AL$39,報告用!$E$4:$E$39,"",FALSE))
B11: =_xlfn.XLOOKUP(ROW(B11)-ROW(B$4),報告用!$AC$4:$AC$39,報告用!F$4:F$39,"",FALSE) | C11: =_xlfn.XLOOKUP(ROW(C11)-ROW(C$4),報告用!$AC$4:$AC$39,報告用!G$4:G$39,"",FALSE) | D11: =IF(C11="","","様") | E11: =IF(_xlfn.XLOOKUP(ROW(E11)-ROW(E$4),報告用!$AC$4:$AC$39,報告用!E$4:E$39,"",FALSE)=B11,"",_xlfn.XLOOKUP(ROW(E11)-ROW(E$4),報告用!$AC$4:$AC$39,報告用!E$4:E$39,"",FALSE)) | H11: =_xlfn.XLOOKUP(ROW(H11)-ROW(H$8),報告用!$AK$4:$AK$39,報告用!$F$4:$F$39,"",FALSE) -> 16 | I11: =_xlfn.XLOOKUP(ROW(I11)-ROW(I$8),報告用!$AK$4:$AK$39,報告用!$G$4:$G$39,"",FALSE) -> 笠井 京子 | J11: =IF(I11="","","様") -> 様 | K11: =IF(_xlfn.XLOOKUP(ROW(K11)-ROW(K$8),報告用!$AK$4:$AK$39,報告用!$E$4:$E$39,"",FALSE)=H11,"",_xlfn.XLOOKUP(ROW(K11)-ROW(K$8),報告用!$AK$4:$AK$39,報告用!$E$4:$E$39,"",FALSE)) | N11: =_xlfn.XLOOKUP(ROW(N11)-ROW(N$8),報告用!$AL$4:$AL$39,報告用!$F$4:$F$39,"",FALSE) -> 16 | O11: =_xlfn.XLOOKUP(ROW(O11)-ROW(O$8),報告用!$AL$4:$AL$39,報告用!$G$4:$G$39,"",FALSE) -> 牛山 はつ子 | P11: =IF(O11="","","様") -> 様 | Q11: =IF(_xlfn.XLOOKUP(ROW(Q11)-ROW(Q$8),報告用!$AL$4:$AL$39,報告用!$E$4:$E$39,"",FALSE)=N11,"",_xlfn.XLOOKUP(ROW(Q11)-ROW(Q$8),報告用!$AL$4:$AL$39,報告用!$E$4:$E$39,"",FALSE))
B12: =_xlfn.XLOOKUP(ROW(B12)-ROW(B$4),報告用!$AC$4:$AC$39,報告用!F$4:F$39,"",FALSE) | C12: =_xlfn.XLOOKUP(ROW(C12)-ROW(C$4),報告用!$AC$4:$AC$39,報告用!G$4:G$39,"",FALSE) | D12: =IF(C12="","","様") | E12: =IF(_xlfn.XLOOKUP(ROW(E12)-ROW(E$4),報告用!$AC$4:$AC$39,報告用!E$4:E$39,"",FALSE)=B12,"",_xlfn.XLOOKUP(ROW(E12)-ROW(E$4),報告用!$AC$4:$AC$39,報告用!E$4:E$39,"",FALSE)) | H12: =_xlfn.XLOOKUP(ROW(H12)-ROW(H$8),報告用!$AK$4:$AK$39,報告用!$F$4:$F$39,"",FALSE) -> 16 | I12: =_xlfn.XLOOKUP(ROW(I12)-ROW(I$8),報告用!$AK$4:$AK$39,報告用!$G$4:$G$39,"",FALSE) -> 牛山 はつ子 | J12: =IF(I12="","","様") -> 様 | K12: =IF(_xlfn.XLOOKUP(ROW(K12)-ROW(K$8),報告用!$AK$4:$AK$39,報告用!$E$4:$E$39,"",FALSE)=H12,"",_xlfn.XLOOKUP(ROW(K12)-ROW(K$8),報告用!$AK$4:$AK$39,報告用!$E$4:$E$39,"",FALSE)) | N12: =_xlfn.XLOOKUP(ROW(N12)-ROW(N$8),報告用!$AL$4:$AL$39,報告用!$F$4:$F$39,"",FALSE) -> 16 | O12: =_xlfn.XLOOKUP(ROW(O12)-ROW(O$8),報告用!$AL$4:$AL$39,報告用!$G$4:$G$39,"",FALSE) -> 西山 望 | P12: =IF(O12="","","様") -> 様 | Q12: =IF(_xlfn.XLOOKUP(ROW(Q12)-ROW(Q$8),報告用!$AL$4:$AL$39,報告用!$E$4:$E$39,"",FALSE)=N12,"",_xlfn.XLOOKUP(ROW(Q12)-ROW(Q$8),報告用!$AL$4:$AL$39,報告用!$E$4:$E$39,"",FALSE))
A13: 昼 のみ | B13: =_xlfn.XLOOKUP(ROW(B13)-ROW(B$12),報告用!$AD$4:$AD$39,報告用!F$4:F$39,"",FALSE) -> 16 | C13: =_xlfn.XLOOKUP(ROW(C13)-ROW(C$12),報告用!$AD$4:$AD$39,報告用!G$4:G$39,"",FALSE) -> 牛山 はつ子 | D13: =IF(C13="","","様") -> 様 | E13: =IF(_xlfn.XLOOKUP(ROW(E13)-ROW(E$12),報告用!$AD$4:$AD$39,報告用!E$4:E$39,"",FALSE)=B13,"",_xlfn.XLOOKUP(ROW(E13)-ROW(E$12),報告用!$AD$4:$AD$39,報告用!E$4:E$39,"",FALSE)) | H13: =_xlfn.XLOOKUP(ROW(H13)-ROW(H$8),報告用!$AK$4:$AK$39,報告用!$F$4:$F$39,"",FALSE) -> 16 | I13: =_xlfn.XLOOKUP(ROW(I13)-ROW(I$8),報告用!$AK$4:$AK$39,報告用!$G$4:$G$39,"",FALSE) -> 西山 望 | J13: =IF(I13="","","様") -> 様 | K13: =IF(_xlfn.XLOOKUP(ROW(K13)-ROW(K$8),報告用!$AK$4:$AK$39,報告用!$E$4:$E$39,"",FALSE)=H13,"",_xlfn.XLOOKUP(ROW(K13)-ROW(K$8),報告用!$AK$4:$AK$39,報告用!$E$4:$E$39,"",FALSE)) | N13: =_xlfn.XLOOKUP(ROW(N13)-ROW(N$8),報告用!$AL$4:$AL$39,報告用!$F$4:$F$39,"",FALSE) -> 17 | O13: =_xlfn.XLOOKUP(ROW(O13)-ROW(O$8),報告用!$AL$4:$AL$39,報告用!$G$4:$G$39,"",FALSE) -> 斎藤 潤一 | P13: =IF(O13="","","様") -> 様 | Q13: =IF(_xlfn.XLOOKUP(ROW(Q13)-ROW(Q$8),報告用!$AL$4:$AL$39,報告用!$E$4:$E$39,"",FALSE)=N13,"",_xlfn.XLOOKUP(ROW(Q13)-ROW(Q$8),報告用!$AL$4:$AL$39,報告用!$E$4:$E$39,"",FALSE))
B14: =_xlfn.XLOOKUP(ROW(B14)-ROW(B$12),報告用!$AD$4:$AD$39,報告用!F$4:F$39,"",FALSE) -> 16 | C14: =_xlfn.XLOOKUP(ROW(C14)-ROW(C$12),報告用!$AD$4:$AD$39,報告用!G$4:G$39,"",FALSE) -> 森 たい子 | D14: =IF(C14="","","様") -> 様 | E14: =IF(_xlfn.XLOOKUP(ROW(E14)-ROW(E$12),報告用!$AD$4:$AD$39,報告用!E$4:E$39,"",FALSE)=B14,"",_xlfn.XLOOKUP(ROW(E14)-ROW(E$12),報告用!$AD$4:$AD$39,報告用!E$4:E$39,"",FALSE)) | H14: =_xlfn.XLOOKUP(ROW(H14)-ROW(H$8),報告用!$AK$4:$AK$39,報告用!$F$4:$F$39,"",FALSE) -> 17 | I14: =_xlfn.XLOOKUP(ROW(I14)-ROW(I$8),報告用!$AK$4:$AK$39,報告用!$G$4:$G$39,"",FALSE) -> 斎藤 潤一 | J14: =IF(I14="","","様") -> 様 | K14: =IF(_xlfn.XLOOKUP(ROW(K14)-ROW(K$8),報告用!$AK$4:$AK$39,報告用!$E$4:$E$39,"",FALSE)=H14,"",_xlfn.XLOOKUP(ROW(K14)-ROW(K$8),報告用!$AK$4:$AK$39,報告用!$E$4:$E$39,"",FALSE)) | N14: =_xlfn.XLOOKUP(ROW(N14)-ROW(N$8),報告用!$AL$4:$AL$39,報告用!$F$4:$F$39,"",FALSE) -> 18 | O14: =_xlfn.XLOOKUP(ROW(O14)-ROW(O$8),報告用!$AL$4:$AL$39,報告用!$G$4:$G$39,"",FALSE) -> 中澤 和江 | P14: =IF(O14="","","様") -> 様 | Q14: =IF(_xlfn.XLOOKUP(ROW(Q14)-ROW(Q$8),報告用!$AL$4:$AL$39,報告用!$E$4:$E$39,"",FALSE)=N14,"",_xlfn.XLOOKUP(ROW(Q14)-ROW(Q$8),報告用!$AL$4:$AL$39,報告用!$E$4:$E$39,"",FALSE)) -> 17
B15: =_xlfn.XLOOKUP(ROW(B15)-ROW(B$12),報告用!$AD$4:$AD$39,報告用!F$4:F$39,"",FALSE) -> 17 | C15: =_xlfn.XLOOKUP(ROW(C15)-ROW(C$12),報告用!$AD$4:$AD$39,報告用!G$4:G$39,"",FALSE) -> 小澤 俊治 | D15: =IF(C15="","","様") -> 様 | E15: =IF(_xlfn.XLOOKUP(ROW(E15)-ROW(E$12),報告用!$AD$4:$AD$39,報告用!E$4:E$39,"",FALSE)=B15,"",_xlfn.XLOOKUP(ROW(E15)-ROW(E$12),報告用!$AD$4:$AD$39,報告用!E$4:E$39,"",FALSE)) | H15: =_xlfn.XLOOKUP(ROW(H15)-ROW(H$8),報告用!$AK$4:$AK$39,報告用!$F$4:$F$39,"",FALSE) -> 18 | I15: =_xlfn.XLOOKUP(ROW(I15)-ROW(I$8),報告用!$AK$4:$AK$39,報告用!$G$4:$G$39,"",FALSE) -> 中澤 和江 | J15: =IF(I15="","","様") -> 様 | K15: =IF(_xlfn.XLOOKUP(ROW(K15)-ROW(K$8),報告用!$AK$4:$AK$39,報告用!$E$4:$E$39,"",FALSE)=H15,"",_xlfn.XLOOKUP(ROW(K15)-ROW(K$8),報告用!$AK$4:$AK$39,報告用!$E$4:$E$39,"",FALSE)) -> 17 | N15: =_xlfn.XLOOKUP(ROW(N15)-ROW(N$8),報告用!$AL$4:$AL$39,報告用!$F$4:$F$39,"",FALSE) -> 18 | O15: =_xlfn.XLOOKUP(ROW(O15)-ROW(O$8),報告用!$AL$4:$AL$39,報告用!$G$4:$G$39,"",FALSE) -> 山本 たみ子 | P15: =IF(O15="","","様") -> 様 | Q15: =IF(_xlfn.XLOOKUP(ROW(Q15)-ROW(Q$8),報告用!$AL$4:$AL$39,報告用!$E$4:$E$39,"",FALSE)=N15,"",_xlfn.XLOOKUP(ROW(Q15)-ROW(Q$8),報告用!$AL$4:$AL$39,報告用!$E$4:$E$39,"",FALSE))
B16: =_xlfn.XLOOKUP(ROW(B16)-ROW(B$12),報告用!$AD$4:$AD$39,報告用!F$4:F$39,"",FALSE) -> 21 | C16: =_xlfn.XLOOKUP(ROW(C16)-ROW(C$12),報告用!$AD$4:$AD$39,報告用!G$4:G$39,"",FALSE) -> 土田 茂 | D16: =IF(C16="","","様") -> 様 | E16: =IF(_xlfn.XLOOKUP(ROW(E16)-ROW(E$12),報告用!$AD$4:$AD$39,報告用!E$4:E$39,"",FALSE)=B16,"",_xlfn.XLOOKUP(ROW(E16)-ROW(E$12),報告用!$AD$4:$AD$39,報告用!E$4:E$39,"",FALSE)) | H16: =_xlfn.XLOOKUP(ROW(H16)-ROW(H$8),報告用!$AK$4:$AK$39,報告用!$F$4:$F$39,"",FALSE) -> 18 | I16: =_xlfn.XLOOKUP(ROW(I16)-ROW(I$8),報告用!$AK$4:$AK$39,報告用!$G$4:$G$39,"",FALSE) -> 深味 照子 | J16: =IF(I16="","","様") -> 様 | K16: =IF(_xlfn.XLOOKUP(ROW(K16)-ROW(K$8),報告用!$AK$4:$AK$39,報告用!$E$4:$E$39,"",FALSE)=H16,"",_xlfn.XLOOKUP(ROW(K16)-ROW(K$8),報告用!$AK$4:$AK$39,報告用!$E$4:$E$39,"",FALSE)) | N16: =_xlfn.XLOOKUP(ROW(N16)-ROW(N$8),報告用!$AL$4:$AL$39,報告用!$F$4:$F$39,"",FALSE) -> 20 | O16: =_xlfn.XLOOKUP(ROW(O16)-ROW(O$8),報告用!$AL$4:$AL$39,報告用!$G$4:$G$39,"",FALSE) -> 小口 千穂 | P16: =IF(O16="","","様") -> 様 | Q16: =IF(_xlfn.XLOOKUP(ROW(Q16)-ROW(Q$8),報告用!$AL$4:$AL$39,報告用!$E$4:$E$39,"",FALSE)=N16,"",_xlfn.XLOOKUP(ROW(Q16)-ROW(Q$8),報告用!$AL$4:$AL$39,報告用!$E$4:$E$39,"",FALSE))
B17: =_xlfn.XLOOKUP(ROW(B17)-ROW(B$12),報告用!$AD$4:$AD$39,報告用!F$4:F$39,"",FALSE) | C17: =_xlfn.XLOOKUP(ROW(C17)-ROW(C$12),報告用!$AD$4:$AD$39,報告用!G$4:G$39,"",FALSE) | D17: =IF(C17="","","様") | E17: =IF(_xlfn.XLOOKUP(ROW(E17)-ROW(E$12),報告用!$AD$4:$AD$39,報告用!E$4:E$39,"",FALSE)=B17,"",_xlfn.XLOOKUP(ROW(E17)-ROW(E$12),報告用!$AD$4:$AD$39,報告用!E$4:E$39,"",FALSE)) | H17: =_xlfn.XLOOKUP(ROW(H17)-ROW(H$8),報告用!$AK$4:$AK$39,報告用!$F$4:$F$39,"",FALSE) -> 18 | I17: =_xlfn.XLOOKUP(ROW(I17)-ROW(I$8),報告用!$AK$4:$AK$39,報告用!$G$4:$G$39,"",FALSE) -> 山本 たみ子 | J17: =IF(I17="","","様") -> 様 | K17: =IF(_xlfn.XLOOKUP(ROW(K17)-ROW(K$8),報告用!$AK$4:$AK$39,報告用!$E$4:$E$39,"",FALSE)=H17,"",_xlfn.XLOOKUP(ROW(K17)-ROW(K$8),報告用!$AK$4:$AK$39,報告用!$E$4:$E$39,"",FALSE)) | N17: =_xlfn.XLOOKUP(ROW(N17)-ROW(N$8),報告用!$AL$4:$AL$39,報告用!$F$4:$F$39,"",FALSE) -> 20 | O17: =_xlfn.XLOOKUP(ROW(O17)-ROW(O$8),報告用!$AL$4:$AL$39,報告用!$G$4:$G$39,"",FALSE) -> 堀内 竹子 | P17: =IF(O17="","","様") -> 様 | Q17: =IF(_xlfn.XLOOKUP(ROW(Q17)-ROW(Q$8),報告用!$AL$4:$AL$39,報告用!$E$4:$E$39,"",FALSE)=N17,"",_xlfn.XLOOKUP(ROW(Q17)-ROW(Q$8),報告用!$AL$4:$AL$39,報告用!$E$4:$E$39,"",FALSE))
B18: =_xlfn.XLOOKUP(ROW(B18)-ROW(B$12),報告用!$AD$4:$AD$39,報告用!F$4:F$39,"",FALSE) | C18: =_xlfn.XLOOKUP(ROW(C18)-ROW(C$12),報告用!$AD$4:$AD$39,報告用!G$4:G$39,"",FALSE) | D18: =IF(C18="","","様") | E18: =IF(_xlfn.XLOOKUP(ROW(E18)-ROW(E$12),報告用!$AD$4:$AD$39,報告用!E$4:E$39,"",FALSE)=B18,"",_xlfn.XLOOKUP(ROW(E18)-ROW(E$12),報告用!$AD$4:$AD$39,報告用!E$4:E$39,"",FALSE)) | H18: =_xlfn.XLOOKUP(ROW(H18)-ROW(H$8),報告用!$AK$4:$AK$39,報告用!$F$4:$F$39,"",FALSE) -> 20 | I18: =_xlfn.XLOOKUP(ROW(I18)-ROW(I$8),報告用!$AK$4:$AK$39,報告用!$G$4:$G$39,"",FALSE) -> 小口 千穂 | J18: =IF(I18="","","様") -> 様 | K18: =IF(_xlfn.XLOOKUP(ROW(K18)-ROW(K$8),報告用!$AK$4:$AK$39,報告用!$E$4:$E$39,"",FALSE)=H18,"",_xlfn.XLOOKUP(ROW(K18)-ROW(K$8),報告用!$AK$4:$AK$39,報告用!$E$4:$E$39,"",FALSE)) | N18: =_xlfn.XLOOKUP(ROW(N18)-ROW(N$8),報告用!$AL$4:$AL$39,報告用!$F$4:$F$39,"",FALSE) -> 21 | O18: =_xlfn.XLOOKUP(ROW(O18)-ROW(O$8),報告用!$AL$4:$AL$39,報告用!$G$4:$G$39,"",FALSE) -> 小林 國光 | P18: =IF(O18="","","様") -> 様 | Q18: =IF(_xlfn.XLOOKUP(ROW(Q18)-ROW(Q$8),報告用!$AL$4:$AL$39,報告用!$E$4:$E$39,"",FALSE)=N18,"",_xlfn.XLOOKUP(ROW(Q18)-ROW(Q$8),報告用!$AL$4:$AL$39,報告用!$E$4:$E$39,"",FALSE)) -> 17
B19: =_xlfn.XLOOKUP(ROW(B19)-ROW(B$12),報告用!$AD$4:$AD$39,報告用!F$4:F$39,"",FALSE) | C19: =_xlfn.XLOOKUP(ROW(C19)-ROW(C$12),報告用!$AD$4:$AD$39,報告用!G$4:G$39,"",FALSE) | D19: =IF(C19="","","様") | E19: =IF(_xlfn.XLOOKUP(ROW(E19)-ROW(E$12),報告用!$AD$4:$AD$39,報告用!E$4:E$39,"",FALSE)=B19,"",_xlfn.XLOOKUP(ROW(E19)-ROW(E$12),報告用!$AD$4:$AD$39,報告用!E$4:E$39,"",FALSE)) | H19: =_xlfn.XLOOKUP(ROW(H19)-ROW(H$8),報告用!$AK$4:$AK$39,報告用!$F$4:$F$39,"",FALSE) -> 20 | I19: =_xlfn.XLOOKUP(ROW(I19)-ROW(I$8),報告用!$AK$4:$AK$39,報告用!$G$4:$G$39,"",FALSE) -> 堀内 竹子 | J19: =IF(I19="","","様") -> 様 | K19: =IF(_xlfn.XLOOKUP(ROW(K19)-ROW(K$8),報告用!$AK$4:$AK$39,報告用!$E$4:$E$39,"",FALSE)=H19,"",_xlfn.XLOOKUP(ROW(K19)-ROW(K$8),報告用!$AK$4:$AK$39,報告用!$E$4:$E$39,"",FALSE)) | N19: =_xlfn.XLOOKUP(ROW(N19)-ROW(N$8),報告用!$AL$4:$AL$39,報告用!$F$4:$F$39,"",FALSE) -> 21 | O19: =_xlfn.XLOOKUP(ROW(O19)-ROW(O$8),報告用!$AL$4:$AL$39,報告用!$G$4:$G$39,"",FALSE) -> 土田 茂 | P19: =IF(O19="","","様") -> 様 | Q19: =IF(_xlfn.XLOOKUP(ROW(Q19)-ROW(Q$8),報告用!$AL$4:$AL$39,報告用!$E$4:$E$39,"",FALSE)=N19,"",_xlfn.XLOOKUP(ROW(Q19)-ROW(Q$8),報告用!$AL$4:$AL$39,報告用!$E$4:$E$39,"",FALSE))
B20: =_xlfn.XLOOKUP(ROW(B20)-ROW(B$12),報告用!$AD$4:$AD$39,報告用!F$4:F$39,"",FALSE) | C20: =_xlfn.XLOOKUP(ROW(C20)-ROW(C$12),報告用!$AD$4:$AD$39,報告用!G$4:G$39,"",FALSE) | D20: =IF(C20="","","様") | E20: =IF(_xlfn.XLOOKUP(ROW(E20)-ROW(E$12),報告用!$AD$4:$AD$39,報告用!E$4:E$39,"",FALSE)=B20,"",_xlfn.XLOOKUP(ROW(E20)-ROW(E$12),報告用!$AD$4:$AD$39,報告用!E$4:E$39,"",FALSE)) | H20: =_xlfn.XLOOKUP(ROW(H20)-ROW(H$8),報告用!$AK$4:$AK$39,報告用!$F$4:$F$39,"",FALSE) -> 21 | I20: =_xlfn.XLOOKUP(ROW(I20)-ROW(I$8),報告用!$AK$4:$AK$39,報告用!$G$4:$G$39,"",FALSE) -> 小林 國光 | J20: =IF(I20="","","様") -> 様 | K20: =IF(_xlfn.XLOOKUP(ROW(K20)-ROW(K$8),報告用!$AK$4:$AK$39,報告用!$E$4:$E$39,"",FALSE)=H20,"",_xlfn.XLOOKUP(ROW(K20)-ROW(K$8),報告用!$AK$4:$AK$39,報告用!$E$4:$E$39,"",FALSE)) -> 17 | N20: =_xlfn.XLOOKUP(ROW(N20)-ROW(N$8),報告用!$AL$4:$AL$39,報告用!$F$4:$F$39,"",FALSE) -> 21 | O20: =_xlfn.XLOOKUP(ROW(O20)-ROW(O$8),報告用!$AL$4:$AL$39,報告用!$G$4:$G$39,"",FALSE) -> 加納 鉄也 | P20: =IF(O20="","","様") -> 様 | Q20: =IF(_xlfn.XLOOKUP(ROW(Q20)-ROW(Q$8),報告用!$AL$4:$AL$39,報告用!$E$4:$E$39,"",FALSE)=N20,"",_xlfn.XLOOKUP(ROW(Q20)-ROW(Q$8),報告用!$AL$4:$AL$39,報告用!$E$4:$E$39,"",FALSE)) -> 16
G21: Aグループ
M22: =報告用!$O$2 -> 46106
A23: 離床 | B23: 水 | G23: 離床 | H23: 木 | M23: 離床 | N23: 金
B24: 部屋 | C24: 氏名 | E24: 車庫 | H24: 部屋 | I24: 氏名 | K24: 車庫 | N24: 部屋 | O24: 氏名 | Q24: 車庫
A25: AM | B25: =_xlfn.XLOOKUP(ROW(B25)-ROW(B$24),報告用!$AH$4:$AH$39,報告用!$F$4:$F$39,"",FALSE) -> 15 | C25: =_xlfn.XLOOKUP(ROW(C25)-ROW(C$24),報告用!$AH$4:$AH$39,報告用!$G$4:$G$39,"",FALSE) -> 志村とも子 | D25: =IF(C25="","","様") -> 様 | E25: =IF(_xlfn.XLOOKUP(ROW(E25)-ROW(E$24),報告用!$AH$4:$AH$39,報告用!$E$4:$E$39,"",FALSE)=B25,"",_xlfn.XLOOKUP(ROW(E25)-ROW(E$24),報告用!$AH$4:$AH$39,報告用!$E$4:$E$39,"",FALSE)) | G25: AM | H25: =_xlfn.XLOOKUP(ROW(H25)-ROW(H$24),報告用!$AI$4:$AI$39,報告用!$F$4:$F$39,"",FALSE) -> 15 | I25: =_xlfn.XLOOKUP(ROW(I25)-ROW(I$24),報告用!$AI$4:$AI$39,報告用!$G$4:$G$39,"",FALSE) -> 志村とも子 | J25: =IF(I25="","","様") -> 様 | K25: =IF(_xlfn.XLOOKUP(ROW(K25)-ROW(K$24),報告用!$AI$4:$AI$39,報告用!$E$4:$E$39,"",FALSE)=H25,"",_xlfn.XLOOKUP(ROW(K25)-ROW(K$24),報告用!$AI$4:$AI$39,報告用!$E$4:$E$39,"",FALSE)) | M25: AM | N25: =_xlfn.XLOOKUP(ROW(N25)-ROW(N$24),報告用!$AJ$4:$AJ$39,報告用!$F$4:$F$39,"",FALSE) -> 15 | O25: =_xlfn.XLOOKUP(ROW(O25)-ROW(O$24),報告用!$AJ$4:$AJ$39,報告用!$G$4:$G$39,"",FALSE) -> 志村とも子 | P25: =IF(O25="","","様") -> 様 | Q25: =IF(_xlfn.XLOOKUP(ROW(Q25)-ROW(Q$24),報告用!$AJ$4:$AJ$39,報告用!$E$4:$E$39,"",FALSE)=N25,"",_xlfn.XLOOKUP(ROW(Q25)-ROW(Q$24),報告用!$AJ$4:$AJ$39,報告用!$E$4:$E$39,"",FALSE))
B26: =_xlfn.XLOOKUP(ROW(B26)-ROW(B$24),報告用!$AH$4:$AH$39,報告用!$F$4:$F$39,"",FALSE) -> 15 | C26: =_xlfn.XLOOKUP(ROW(C26)-ROW(C$24),報告用!$AH$4:$AH$39,報告用!$G$4:$G$39,"",FALSE) -> 飯室 純江 | D26: =IF(C26="","","様") -> 様 | E26: =IF(_xlfn.XLOOKUP(ROW(E26)-ROW(E$24),報告用!$AH$4:$AH$39,報告用!$E$4:$E$39,"",FALSE)=B26,"",_xlfn.XLOOKUP(ROW(E26)-ROW(E$24),報告用!$AH$4:$AH$39,報告用!$E$4:$E$39,"",FALSE)) | H26: =_xlfn.XLOOKUP(ROW(H26)-ROW(H$24),報告用!$AI$4:$AI$39,報告用!$F$4:$F$39,"",FALSE) -> 15 | I26: =_xlfn.XLOOKUP(ROW(I26)-ROW(I$24),報告用!$AI$4:$AI$39,報告用!$G$4:$G$39,"",FALSE) -> 望月 美希 | J26: =IF(I26="","","様") -> 様 | K26: =IF(_xlfn.XLOOKUP(ROW(K26)-ROW(K$24),報告用!$AI$4:$AI$39,報告用!$E$4:$E$39,"",FALSE)=H26,"",_xlfn.XLOOKUP(ROW(K26)-ROW(K$24),報告用!$AI$4:$AI$39,報告用!$E$4:$E$39,"",FALSE)) | N26: =_xlfn.XLOOKUP(ROW(N26)-ROW(N$24),報告用!$AJ$4:$AJ$39,報告用!$F$4:$F$39,"",FALSE) -> 16 | O26: =_xlfn.XLOOKUP(ROW(O26)-ROW(O$24),報告用!$AJ$4:$AJ$39,報告用!$G$4:$G$39,"",FALSE) -> 里吉 松子 | P26: =IF(O26="","","様") -> 様 | Q26: =IF(_xlfn.XLOOKUP(ROW(Q26)-ROW(Q$24),報告用!$AJ$4:$AJ$39,報告用!$E$4:$E$39,"",FALSE)=N26,"",_xlfn.XLOOKUP(ROW(Q26)-ROW(Q$24),報告用!$AJ$4:$AJ$39,報告用!$E$4:$E$39,"",FALSE))
B27: =_xlfn.XLOOKUP(ROW(B27)-ROW(B$24),報告用!$AH$4:$AH$39,報告用!$F$4:$F$39,"",FALSE) -> 16 | C27: =_xlfn.XLOOKUP(ROW(C27)-ROW(C$24),報告用!$AH$4:$AH$39,報告用!$G$4:$G$39,"",FALSE) -> 里吉 松子 | D27: =IF(C27="","","様") -> 様 | E27: =IF(_xlfn.XLOOKUP(ROW(E27)-ROW(E$24),報告用!$AH$4:$AH$39,報告用!$E$4:$E$39,"",FALSE)=B27,"",_xlfn.XLOOKUP(ROW(E27)-ROW(E$24),報告用!$AH$4:$AH$39,報告用!$E$4:$E$39,"",FALSE)) | H27: =_xlfn.XLOOKUP(ROW(H27)-ROW(H$24),報告用!$AI$4:$AI$39,報告用!$F$4:$F$39,"",FALSE) -> 16 | I27: =_xlfn.XLOOKUP(ROW(I27)-ROW(I$24),報告用!$AI$4:$AI$39,報告用!$G$4:$G$39,"",FALSE) -> 里吉 松子 | J27: =IF(I27="","","様") -> 様 | K27: =IF(_xlfn.XLOOKUP(ROW(K27)-ROW(K$24),報告用!$AI$4:$AI$39,報告用!$E$4:$E$39,"",FALSE)=H27,"",_xlfn.XLOOKUP(ROW(K27)-ROW(K$24),報告用!$AI$4:$AI$39,報告用!$E$4:$E$39,"",FALSE)) | N27: =_xlfn.XLOOKUP(ROW(N27)-ROW(N$24),報告用!$AJ$4:$AJ$39,報告用!$F$4:$F$39,"",FALSE) -> 16 | O27: =_xlfn.XLOOKUP(ROW(O27)-ROW(O$24),報告用!$AJ$4:$AJ$39,報告用!$G$4:$G$39,"",FALSE) -> 森 たい子 | P27: =IF(O27="","","様") -> 様 | Q27: =IF(_xlfn.XLOOKUP(ROW(Q27)-ROW(Q$24),報告用!$AJ$4:$AJ$39,報告用!$E$4:$E$39,"",FALSE)=N27,"",_xlfn.XLOOKUP(ROW(Q27)-ROW(Q$24),報告用!$AJ$4:$AJ$39,報告用!$E$4:$E$39,"",FALSE))
B28: =_xlfn.XLOOKUP(ROW(B28)-ROW(B$24),報告用!$AH$4:$AH$39,報告用!$F$4:$F$39,"",FALSE) -> 16 | C28: =_xlfn.XLOOKUP(ROW(C28)-ROW(C$24),報告用!$AH$4:$AH$39,報告用!$G$4:$G$39,"",FALSE) -> 森 たい子 | D28: =IF(C28="","","様") -> 様 | E28: =IF(_xlfn.XLOOKUP(ROW(E28)-ROW(E$24),報告用!$AH$4:$AH$39,報告用!$E$4:$E$39,"",FALSE)=B28,"",_xlfn.XLOOKUP(ROW(E28)-ROW(E$24),報告用!$AH$4:$AH$39,報告用!$E$4:$E$39,"",FALSE)) | H28: =_xlfn.XLOOKUP(ROW(H28)-ROW(H$24),報告用!$AI$4:$AI$39,報告用!$F$4:$F$39,"",FALSE) -> 16 | I28: =_xlfn.XLOOKUP(ROW(I28)-ROW(I$24),報告用!$AI$4:$AI$39,報告用!$G$4:$G$39,"",FALSE) -> 森 たい子 | J28: =IF(I28="","","様") -> 様 | K28: =IF(_xlfn.XLOOKUP(ROW(K28)-ROW(K$24),報告用!$AI$4:$AI$39,報告用!$E$4:$E$39,"",FALSE)=H28,"",_xlfn.XLOOKUP(ROW(K28)-ROW(K$24),報告用!$AI$4:$AI$39,報告用!$E$4:$E$39,"",FALSE)) | N28: =_xlfn.XLOOKUP(ROW(N28)-ROW(N$24),報告用!$AJ$4:$AJ$39,報告用!$F$4:$F$39,"",FALSE) -> 17 | O28: =_xlfn.XLOOKUP(ROW(O28)-ROW(O$24),報告用!$AJ$4:$AJ$39,報告用!$G$4:$G$39,"",FALSE) -> 河野 秀夫 | P28: =IF(O28="","","様") -> 様 | Q28: =IF(_xlfn.XLOOKUP(ROW(Q28)-ROW(Q$24),報告用!$AJ$4:$AJ$39,報告用!$E$4:$E$39,"",FALSE)=N28,"",_xlfn.XLOOKUP(ROW(Q28)-ROW(Q$24),報告用!$AJ$4:$AJ$39,報告用!$E$4:$E$39,"",FALSE))
A29: PM | B29: =_xlfn.XLOOKUP(ROW(B29)-ROW(B$28),報告用!$AM$4:$AM$39,報告用!$F$4:$F$39,"",FALSE) -> 15 | C29: =_xlfn.XLOOKUP(ROW(C29)-ROW(C$28),報告用!$AM$4:$AM$39,報告用!$G$4:$G$39,"",FALSE) -> 志村とも子 | D29: =IF(C29="","","様") -> 様 | E29: =IF(_xlfn.XLOOKUP(ROW(E29)-ROW(E$28),報告用!$AM$4:$AM$39,報告用!$E$4:$E$39,"",FALSE)=B29,"",_xlfn.XLOOKUP(ROW(E29)-ROW(E$28),報告用!$AM$4:$AM$39,報告用!$E$4:$E$39,"",FALSE)) | G29: PM | H29: =_xlfn.XLOOKUP(ROW(H29)-ROW(H$28),報告用!$AN$4:$AN$39,報告用!$F$4:$F$39,"",FALSE) -> 15 | I29: =_xlfn.XLOOKUP(ROW(I29)-ROW(I$28),報告用!$AN$4:$AN$39,報告用!$G$4:$G$39,"",FALSE) -> 志村とも子 | J29: =IF(I29="","","様") -> 様 | K29: =IF(_xlfn.XLOOKUP(ROW(K29)-ROW(K$28),報告用!$AN$4:$AN$39,報告用!$E$4:$E$39,"",FALSE)=H29,"",_xlfn.XLOOKUP(ROW(K29)-ROW(K$28),報告用!$AN$4:$AN$39,報告用!$E$4:$E$39,"",FALSE)) | M29: PM | N29: =_xlfn.XLOOKUP(ROW(N29)-ROW(N$28),報告用!$AO$4:$AO$39,報告用!$F$4:$F$39,"",FALSE) -> 15 | O29: =_xlfn.XLOOKUP(ROW(O29)-ROW(O$28),報告用!$AO$4:$AO$39,報告用!$G$4:$G$39,"",FALSE) -> 志村とも子 | P29: =IF(O29="","","様") -> 様 | Q29: =IF(_xlfn.XLOOKUP(ROW(Q29)-ROW(Q$28),報告用!$AO$4:$AO$39,報告用!$E$4:$E$39,"",FALSE)=N29,"",_xlfn.XLOOKUP(ROW(Q29)-ROW(Q$28),報告用!$AO$4:$AO$39,報告用!$E$4:$E$39,"",FALSE))
B30: =_xlfn.XLOOKUP(ROW(B30)-ROW(B$28),報告用!$AM$4:$AM$39,報告用!$F$4:$F$39,"",FALSE) -> 15 | C30: =_xlfn.XLOOKUP(ROW(C30)-ROW(C$28),報告用!$AM$4:$AM$39,報告用!$G$4:$G$39,"",FALSE) -> 佐藤 亜美 | D30: =IF(C30="","","様") -> 様 | E30: =IF(_xlfn.XLOOKUP(ROW(E30)-ROW(E$28),報告用!$AM$4:$AM$39,報告用!$E$4:$E$39,"",FALSE)=B30,"",_xlfn.XLOOKUP(ROW(E30)-ROW(E$28),報告用!$AM$4:$AM$39,報告用!$E$4:$E$39,"",FALSE)) | H30: =_xlfn.XLOOKUP(ROW(H30)-ROW(H$28),報告用!$AN$4:$AN$39,報告用!$F$4:$F$39,"",FALSE) -> 15 | I30: =_xlfn.XLOOKUP(ROW(I30)-ROW(I$28),報告用!$AN$4:$AN$39,報告用!$G$4:$G$39,"",FALSE) -> 佐藤 亜美 | J30: =IF(I30="","","様") -> 様 | K30: =IF(_xlfn.XLOOKUP(ROW(K30)-ROW(K$28),報告用!$AN$4:$AN$39,報告用!$E$4:$E$39,"",FALSE)=H30,"",_xlfn.XLOOKUP(ROW(K30)-ROW(K$28),報告用!$AN$4:$AN$39,報告用!$E$4:$E$39,"",FALSE)) | N30: =_xlfn.XLOOKUP(ROW(N30)-ROW(N$28),報告用!$AO$4:$AO$39,報告用!$F$4:$F$39,"",FALSE) -> 15 | O30: =_xlfn.XLOOKUP(ROW(O30)-ROW(O$28),報告用!$AO$4:$AO$39,報告用!$G$4:$G$39,"",FALSE) -> 佐藤 亜美 | P30: =IF(O30="","","様") -> 様 | Q30: =IF(_xlfn.XLOOKUP(ROW(Q30)-ROW(Q$28),報告用!$AO$4:$AO$39,報告用!$E$4:$E$39,"",FALSE)=N30,"",_xlfn.XLOOKUP(ROW(Q30)-ROW(Q$28),報告用!$AO$4:$AO$39,報告用!$E$4:$E$39,"",FALSE))
B31: =_xlfn.XLOOKUP(ROW(B31)-ROW(B$28),報告用!$AM$4:$AM$39,報告用!$F$4:$F$39,"",FALSE) -> 16 | C31: =_xlfn.XLOOKUP(ROW(C31)-ROW(C$28),報告用!$AM$4:$AM$39,報告用!$G$4:$G$39,"",FALSE) -> 笠井 京子 | D31: =IF(C31="","","様") -> 様 | E31: =IF(_xlfn.XLOOKUP(ROW(E31)-ROW(E$28),報告用!$AM$4:$AM$39,報告用!$E$4:$E$39,"",FALSE)=B31,"",_xlfn.XLOOKUP(ROW(E31)-ROW(E$28),報告用!$AM$4:$AM$39,報告用!$E$4:$E$39,"",FALSE)) | H31: =_xlfn.XLOOKUP(ROW(H31)-ROW(H$28),報告用!$AN$4:$AN$39,報告用!$F$4:$F$39,"",FALSE) -> 16 | I31: =_xlfn.XLOOKUP(ROW(I31)-ROW(I$28),報告用!$AN$4:$AN$39,報告用!$G$4:$G$39,"",FALSE) -> 牛山 はつ子 | J31: =IF(I31="","","様") -> 様 | K31: =IF(_xlfn.XLOOKUP(ROW(K31)-ROW(K$28),報告用!$AN$4:$AN$39,報告用!$E$4:$E$39,"",FALSE)=H31,"",_xlfn.XLOOKUP(ROW(K31)-ROW(K$28),報告用!$AN$4:$AN$39,報告用!$E$4:$E$39,"",FALSE)) | N31: =_xlfn.XLOOKUP(ROW(N31)-ROW(N$28),報告用!$AO$4:$AO$39,報告用!$F$4:$F$39,"",FALSE) -> 16 | O31: =_xlfn.XLOOKUP(ROW(O31)-ROW(O$28),報告用!$AO$4:$AO$39,報告用!$G$4:$G$39,"",FALSE) -> 笠井 京子 | P31: =IF(O31="","","様") -> 様 | Q31: =IF(_xlfn.XLOOKUP(ROW(Q31)-ROW(Q$28),報告用!$AO$4:$AO$39,報告用!$E$4:$E$39,"",FALSE)=N31,"",_xlfn.XLOOKUP(ROW(Q31)-ROW(Q$28),報告用!$AO$4:$AO$39,報告用!$E$4:$E$39,"",FALSE))
B32: =_xlfn.XLOOKUP(ROW(B32)-ROW(B$28),報告用!$AM$4:$AM$39,報告用!$F$4:$F$39,"",FALSE) -> 16 | C32: =_xlfn.XLOOKUP(ROW(C32)-ROW(C$28),報告用!$AM$4:$AM$39,報告用!$G$4:$G$39,"",FALSE) -> 牛山 はつ子 | D32: =IF(C32="","","様") -> 様 | E32: =IF(_xlfn.XLOOKUP(ROW(E32)-ROW(E$28),報告用!$AM$4:$AM$39,報告用!$E$4:$E$39,"",FALSE)=B32,"",_xlfn.XLOOKUP(ROW(E32)-ROW(E$28),報告用!$AM$4:$AM$39,報告用!$E$4:$E$39,"",FALSE)) | H32: =_xlfn.XLOOKUP(ROW(H32)-ROW(H$28),報告用!$AN$4:$AN$39,報告用!$F$4:$F$39,"",FALSE) -> 16 | I32: =_xlfn.XLOOKUP(ROW(I32)-ROW(I$28),報告用!$AN$4:$AN$39,報告用!$G$4:$G$39,"",FALSE) -> 西山 望 | J32: =IF(I32="","","様") -> 様 | K32: =IF(_xlfn.XLOOKUP(ROW(K32)-ROW(K$28),報告用!$AN$4:$AN$39,報告用!$E$4:$E$39,"",FALSE)=H32,"",_xlfn.XLOOKUP(ROW(K32)-ROW(K$28),報告用!$AN$4:$AN$39,報告用!$E$4:$E$39,"",FALSE)) | N32: =_xlfn.XLOOKUP(ROW(N32)-ROW(N$28),報告用!$AO$4:$AO$39,報告用!$F$4:$F$39,"",FALSE) -> 16 | O32: =_xlfn.XLOOKUP(ROW(O32)-ROW(O$28),報告用!$AO$4:$AO$39,報告用!$G$4:$G$39,"",FALSE) -> 牛山 はつ子 | P32: =IF(O32="","","様") -> 様 | Q32: =IF(_xlfn.XLOOKUP(ROW(Q32)-ROW(Q$28),報告用!$AO$4:$AO$39,報告用!$E$4:$E$39,"",FALSE)=N32,"",_xlfn.XLOOKUP(ROW(Q32)-ROW(Q$28),報告用!$AO$4:$AO$39,報告用!$E$4:$E$39,"",FALSE))
B33: =_xlfn.XLOOKUP(ROW(B33)-ROW(B$28),報告用!$AM$4:$AM$39,報告用!$F$4:$F$39,"",FALSE) -> 16 | C33: =_xlfn.XLOOKUP(ROW(C33)-ROW(C$28),報告用!$AM$4:$AM$39,報告用!$G$4:$G$39,"",FALSE) -> 西山 望 | D33: =IF(C33="","","様") -> 様 | E33: =IF(_xlfn.XLOOKUP(ROW(E33)-ROW(E$28),報告用!$AM$4:$AM$39,報告用!$E$4:$E$39,"",FALSE)=B33,"",_xlfn.XLOOKUP(ROW(E33)-ROW(E$28),報告用!$AM$4:$AM$39,報告用!$E$4:$E$39,"",FALSE)) | H33: =_xlfn.XLOOKUP(ROW(H33)-ROW(H$28),報告用!$AN$4:$AN$39,報告用!$F$4:$F$39,"",FALSE) -> 17 | I33: =_xlfn.XLOOKUP(ROW(I33)-ROW(I$28),報告用!$AN$4:$AN$39,報告用!$G$4:$G$39,"",FALSE) -> 斎藤 潤一 | J33: =IF(I33="","","様") -> 様 | K33: =IF(_xlfn.XLOOKUP(ROW(K33)-ROW(K$28),報告用!$AN$4:$AN$39,報告用!$E$4:$E$39,"",FALSE)=H33,"",_xlfn.XLOOKUP(ROW(K33)-ROW(K$28),報告用!$AN$4:$AN$39,報告用!$E$4:$E$39,"",FALSE)) | N33: =_xlfn.XLOOKUP(ROW(N33)-ROW(N$28),報告用!$AO$4:$AO$39,報告用!$F$4:$F$39,"",FALSE) -> 16 | O33: =_xlfn.XLOOKUP(ROW(O33)-ROW(O$28),報告用!$AO$4:$AO$39,報告用!$G$4:$G$39,"",FALSE) -> 西山 望 | P33: =IF(O33="","","様") -> 様 | Q33: =IF(_xlfn.XLOOKUP(ROW(Q33)-ROW(Q$28),報告用!$AO$4:$AO$39,報告用!$E$4:$E$39,"",FALSE)=N33,"",_xlfn.XLOOKUP(ROW(Q33)-ROW(Q$28),報告用!$AO$4:$AO$39,報告用!$E$4:$E$39,"",FALSE))
B34: =_xlfn.XLOOKUP(ROW(B34)-ROW(B$28),報告用!$AM$4:$AM$39,報告用!$F$4:$F$39,"",FALSE) -> 17 | C34: =_xlfn.XLOOKUP(ROW(C34)-ROW(C$28),報告用!$AM$4:$AM$39,報告用!$G$4:$G$39,"",FALSE) -> 斎藤 潤一 | D34: =IF(C34="","","様") -> 様 | E34: =IF(_xlfn.XLOOKUP(ROW(E34)-ROW(E$28),報告用!$AM$4:$AM$39,報告用!$E$4:$E$39,"",FALSE)=B34,"",_xlfn.XLOOKUP(ROW(E34)-ROW(E$28),報告用!$AM$4:$AM$39,報告用!$E$4:$E$39,"",FALSE)) | H34: =_xlfn.XLOOKUP(ROW(H34)-ROW(H$28),報告用!$AN$4:$AN$39,報告用!$F$4:$F$39,"",FALSE) -> 18 | I34: =_xlfn.XLOOKUP(ROW(I34)-ROW(I$28),報告用!$AN$4:$AN$39,報告用!$G$4:$G$39,"",FALSE) -> 中澤 和江 | J34: =IF(I34="","","様") -> 様 | K34: =IF(_xlfn.XLOOKUP(ROW(K34)-ROW(K$28),報告用!$AN$4:$AN$39,報告用!$E$4:$E$39,"",FALSE)=H34,"",_xlfn.XLOOKUP(ROW(K34)-ROW(K$28),報告用!$AN$4:$AN$39,報告用!$E$4:$E$39,"",FALSE)) -> 17 | N34: =_xlfn.XLOOKUP(ROW(N34)-ROW(N$28),報告用!$AO$4:$AO$39,報告用!$F$4:$F$39,"",FALSE) -> 17 | O34: =_xlfn.XLOOKUP(ROW(O34)-ROW(O$28),報告用!$AO$4:$AO$39,報告用!$G$4:$G$39,"",FALSE) -> 斎藤 潤一 | P34: =IF(O34="","","様") -> 様 | Q34: =IF(_xlfn.XLOOKUP(ROW(Q34)-ROW(Q$28),報告用!$AO$4:$AO$39,報告用!$E$4:$E$39,"",FALSE)=N34,"",_xlfn.XLOOKUP(ROW(Q34)-ROW(Q$28),報告用!$AO$4:$AO$39,報告用!$E$4:$E$39,"",FALSE))
B35: =_xlfn.XLOOKUP(ROW(B35)-ROW(B$28),報告用!$AM$4:$AM$39,報告用!$F$4:$F$39,"",FALSE) -> 18 | C35: =_xlfn.XLOOKUP(ROW(C35)-ROW(C$28),報告用!$AM$4:$AM$39,報告用!$G$4:$G$39,"",FALSE) -> 中澤 和江 | D35: =IF(C35="","","様") -> 様 | E35: =IF(_xlfn.XLOOKUP(ROW(E35)-ROW(E$28),報告用!$AM$4:$AM$39,報告用!$E$4:$E$39,"",FALSE)=B35,"",_xlfn.XLOOKUP(ROW(E35)-ROW(E$28),報告用!$AM$4:$AM$39,報告用!$E$4:$E$39,"",FALSE)) -> 17 | H35: =_xlfn.XLOOKUP(ROW(H35)-ROW(H$28),報告用!$AN$4:$AN$39,報告用!$F$4:$F$39,"",FALSE) -> 18 | I35: =_xlfn.XLOOKUP(ROW(I35)-ROW(I$28),報告用!$AN$4:$AN$39,報告用!$G$4:$G$39,"",FALSE) -> 山本 たみ子 | J35: =IF(I35="","","様") -> 様 | K35: =IF(_xlfn.XLOOKUP(ROW(K35)-ROW(K$28),報告用!$AN$4:$AN$39,報告用!$E$4:$E$39,"",FALSE)=H35,"",_xlfn.XLOOKUP(ROW(K35)-ROW(K$28),報告用!$AN$4:$AN$39,報告用!$E$4:$E$39,"",FALSE)) | N35: =_xlfn.XLOOKUP(ROW(N35)-ROW(N$28),報告用!$AO$4:$AO$39,報告用!$F$4:$F$39,"",FALSE) -> 18 | O35: =_xlfn.XLOOKUP(ROW(O35)-ROW(O$28),報告用!$AO$4:$AO$39,報告用!$G$4:$G$39,"",FALSE) -> 中澤 和江 | P35: =IF(O35="","","様") -> 様 | Q35: =IF(_xlfn.XLOOKUP(ROW(Q35)-ROW(Q$28),報告用!$AO$4:$AO$39,報告用!$E$4:$E$39,"",FALSE)=N35,"",_xlfn.XLOOKUP(ROW(Q35)-ROW(Q$28),報告用!$AO$4:$AO$39,報告用!$E$4:$E$39,"",FALSE)) -> 17
B36: =_xlfn.XLOOKUP(ROW(B36)-ROW(B$28),報告用!$AM$4:$AM$39,報告用!$F$4:$F$39,"",FALSE) -> 18 | C36: =_xlfn.XLOOKUP(ROW(C36)-ROW(C$28),報告用!$AM$4:$AM$39,報告用!$G$4:$G$39,"",FALSE) -> 山本 たみ子 | D36: =IF(C36="","","様") -> 様 | E36: =IF(_xlfn.XLOOKUP(ROW(E36)-ROW(E$28),報告用!$AM$4:$AM$39,報告用!$E$4:$E$39,"",FALSE)=B36,"",_xlfn.XLOOKUP(ROW(E36)-ROW(E$28),報告用!$AM$4:$AM$39,報告用!$E$4:$E$39,"",FALSE)) | H36: =_xlfn.XLOOKUP(ROW(H36)-ROW(H$28),報告用!$AN$4:$AN$39,報告用!$F$4:$F$39,"",FALSE) -> 20 | I36: =_xlfn.XLOOKUP(ROW(I36)-ROW(I$28),報告用!$AN$4:$AN$39,報告用!$G$4:$G$39,"",FALSE) -> 小口 千穂 | J36: =IF(I36="","","様") -> 様 | K36: =IF(_xlfn.XLOOKUP(ROW(K36)-ROW(K$28),報告用!$AN$4:$AN$39,報告用!$E$4:$E$39,"",FALSE)=H36,"",_xlfn.XLOOKUP(ROW(K36)-ROW(K$28),報告用!$AN$4:$AN$39,報告用!$E$4:$E$39,"",FALSE)) | N36: =_xlfn.XLOOKUP(ROW(N36)-ROW(N$28),報告用!$AO$4:$AO$39,報告用!$F$4:$F$39,"",FALSE) -> 18 | O36: =_xlfn.XLOOKUP(ROW(O36)-ROW(O$28),報告用!$AO$4:$AO$39,報告用!$G$4:$G$39,"",FALSE) -> 深味 照子 | P36: =IF(O36="","","様") -> 様 | Q36: =IF(_xlfn.XLOOKUP(ROW(Q36)-ROW(Q$28),報告用!$AO$4:$AO$39,報告用!$E$4:$E$39,"",FALSE)=N36,"",_xlfn.XLOOKUP(ROW(Q36)-ROW(Q$28),報告用!$AO$4:$AO$39,報告用!$E$4:$E$39,"",FALSE))
B37: =_xlfn.XLOOKUP(ROW(B37)-ROW(B$28),報告用!$AM$4:$AM$39,報告用!$F$4:$F$39,"",FALSE) -> 20 | C37: =_xlfn.XLOOKUP(ROW(C37)-ROW(C$28),報告用!$AM$4:$AM$39,報告用!$G$4:$G$39,"",FALSE) -> 小口 千穂 | D37: =IF(C37="","","様") -> 様 | E37: =IF(_xlfn.XLOOKUP(ROW(E37)-ROW(E$28),報告用!$AM$4:$AM$39,報告用!$E$4:$E$39,"",FALSE)=B37,"",_xlfn.XLOOKUP(ROW(E37)-ROW(E$28),報告用!$AM$4:$AM$39,報告用!$E$4:$E$39,"",FALSE)) | H37: =_xlfn.XLOOKUP(ROW(H37)-ROW(H$28),報告用!$AN$4:$AN$39,報告用!$F$4:$F$39,"",FALSE) -> 20 | I37: =_xlfn.XLOOKUP(ROW(I37)-ROW(I$28),報告用!$AN$4:$AN$39,報告用!$G$4:$G$39,"",FALSE) -> 堀内 竹子 | J37: =IF(I37="","","様") -> 様 | K37: =IF(_xlfn.XLOOKUP(ROW(K37)-ROW(K$28),報告用!$AN$4:$AN$39,報告用!$E$4:$E$39,"",FALSE)=H37,"",_xlfn.XLOOKUP(ROW(K37)-ROW(K$28),報告用!$AN$4:$AN$39,報告用!$E$4:$E$39,"",FALSE)) | N37: =_xlfn.XLOOKUP(ROW(N37)-ROW(N$28),報告用!$AO$4:$AO$39,報告用!$F$4:$F$39,"",FALSE) -> 18 | O37: =_xlfn.XLOOKUP(ROW(O37)-ROW(O$28),報告用!$AO$4:$AO$39,報告用!$G$4:$G$39,"",FALSE) -> 山本 たみ子 | P37: =IF(O37="","","様") -> 様 | Q37: =IF(_xlfn.XLOOKUP(ROW(Q37)-ROW(Q$28),報告用!$AO$4:$AO$39,報告用!$E$4:$E$39,"",FALSE)=N37,"",_xlfn.XLOOKUP(ROW(Q37)-ROW(Q$28),報告用!$AO$4:$AO$39,報告用!$E$4:$E$39,"",FALSE))
B38: =_xlfn.XLOOKUP(ROW(B38)-ROW(B$28),報告用!$AM$4:$AM$39,報告用!$F$4:$F$39,"",FALSE) -> 20 | C38: =_xlfn.XLOOKUP(ROW(C38)-ROW(C$28),報告用!$AM$4:$AM$39,報告用!$G$4:$G$39,"",FALSE) -> 堀内 竹子 | D38: =IF(C38="","","様") -> 様 | E38: =IF(_xlfn.XLOOKUP(ROW(E38)-ROW(E$28),報告用!$AM$4:$AM$39,報告用!$E$4:$E$39,"",FALSE)=B38,"",_xlfn.XLOOKUP(ROW(E38)-ROW(E$28),報告用!$AM$4:$AM$39,報告用!$E$4:$E$39,"",FALSE)) | H38: =_xlfn.XLOOKUP(ROW(H38)-ROW(H$28),報告用!$AN$4:$AN$39,報告用!$F$4:$F$39,"",FALSE) -> 21 | I38: =_xlfn.XLOOKUP(ROW(I38)-ROW(I$28),報告用!$AN$4:$AN$39,報告用!$G$4:$G$39,"",FALSE) -> 小林 國光 | J38: =IF(I38="","","様") -> 様 | K38: =IF(_xlfn.XLOOKUP(ROW(K38)-ROW(K$28),報告用!$AN$4:$AN$39,報告用!$E$4:$E$39,"",FALSE)=H38,"",_xlfn.XLOOKUP(ROW(K38)-ROW(K$28),報告用!$AN$4:$AN$39,報告用!$E$4:$E$39,"",FALSE)) -> 17 | N38: =_xlfn.XLOOKUP(ROW(N38)-ROW(N$28),報告用!$AO$4:$AO$39,報告用!$F$4:$F$39,"",FALSE) -> 20 | O38: =_xlfn.XLOOKUP(ROW(O38)-ROW(O$28),報告用!$AO$4:$AO$39,報告用!$G$4:$G$39,"",FALSE) -> 小口 千穂 | P38: =IF(O38="","","様") -> 様 | Q38: =IF(_xlfn.XLOOKUP(ROW(Q38)-ROW(Q$28),報告用!$AO$4:$AO$39,報告用!$E$4:$E$39,"",FALSE)=N38,"",_xlfn.XLOOKUP(ROW(Q38)-ROW(Q$28),報告用!$AO$4:$AO$39,報告用!$E$4:$E$39,"",FALSE))
B39: =_xlfn.XLOOKUP(ROW(B39)-ROW(B$28),報告用!$AM$4:$AM$39,報告用!$F$4:$F$39,"",FALSE) -> 21 | C39: =_xlfn.XLOOKUP(ROW(C39)-ROW(C$28),報告用!$AM$4:$AM$39,報告用!$G$4:$G$39,"",FALSE) -> 小林 國光 | D39: =IF(C39="","","様") -> 様 | E39: =IF(_xlfn.XLOOKUP(ROW(E39)-ROW(E$28),報告用!$AM$4:$AM$39,報告用!$E$4:$E$39,"",FALSE)=B39,"",_xlfn.XLOOKUP(ROW(E39)-ROW(E$28),報告用!$AM$4:$AM$39,報告用!$E$4:$E$39,"",FALSE)) -> 17 | H39: =_xlfn.XLOOKUP(ROW(H39)-ROW(H$28),報告用!$AN$4:$AN$39,報告用!$F$4:$F$39,"",FALSE) -> 21 | I39: =_xlfn.XLOOKUP(ROW(I39)-ROW(I$28),報告用!$AN$4:$AN$39,報告用!$G$4:$G$39,"",FALSE) -> 土田 茂 | J39: =IF(I39="","","様") -> 様 | K39: =IF(_xlfn.XLOOKUP(ROW(K39)-ROW(K$28),報告用!$AN$4:$AN$39,報告用!$E$4:$E$39,"",FALSE)=H39,"",_xlfn.XLOOKUP(ROW(K39)-ROW(K$28),報告用!$AN$4:$AN$39,報告用!$E$4:$E$39,"",FALSE)) | N39: =_xlfn.XLOOKUP(ROW(N39)-ROW(N$28),報告用!$AO$4:$AO$39,報告用!$F$4:$F$39,"",FALSE) -> 20 | O39: =_xlfn.XLOOKUP(ROW(O39)-ROW(O$28),報告用!$AO$4:$AO$39,報告用!$G$4:$G$39,"",FALSE) -> 堀内 竹子 | P39: =IF(O39="","","様") -> 様 | Q39: =IF(_xlfn.XLOOKUP(ROW(Q39)-ROW(Q$28),報告用!$AO$4:$AO$39,報告用!$E$4:$E$39,"",FALSE)=N39,"",_xlfn.XLOOKUP(ROW(Q39)-ROW(Q$28),報告用!$AO$4:$AO$39,報告用!$E$4:$E$39,"",FALSE))
B40: =_xlfn.XLOOKUP(ROW(B40)-ROW(B$28),報告用!$AM$4:$AM$39,報告用!$F$4:$F$39,"",FALSE) -> 21 | C40: =_xlfn.XLOOKUP(ROW(C40)-ROW(C$28),報告用!$AM$4:$AM$39,報告用!$G$4:$G$39,"",FALSE) -> 土田 茂 | D40: =IF(C40="","","様") -> 様 | E40: =IF(_xlfn.XLOOKUP(ROW(E40)-ROW(E$28),報告用!$AM$4:$AM$39,報告用!$E$4:$E$39,"",FALSE)=B40,"",_xlfn.XLOOKUP(ROW(E40)-ROW(E$28),報告用!$AM$4:$AM$39,報告用!$E$4:$E$39,"",FALSE)) | H40: =_xlfn.XLOOKUP(ROW(H40)-ROW(H$28),報告用!$AN$4:$AN$39,報告用!$F$4:$F$39,"",FALSE) -> 21 | I40: =_xlfn.XLOOKUP(ROW(I40)-ROW(I$28),報告用!$AN$4:$AN$39,報告用!$G$4:$G$39,"",FALSE) -> 加納 鉄也 | J40: =IF(I40="","","様") -> 様 | K40: =IF(_xlfn.XLOOKUP(ROW(K40)-ROW(K$28),報告用!$AN$4:$AN$39,報告用!$E$4:$E$39,"",FALSE)=H40,"",_xlfn.XLOOKUP(ROW(K40)-ROW(K$28),報告用!$AN$4:$AN$39,報告用!$E$4:$E$39,"",FALSE)) -> 16 | N40: =_xlfn.XLOOKUP(ROW(N40)-ROW(N$28),報告用!$AO$4:$AO$39,報告用!$F$4:$F$39,"",FALSE) -> 21 | O40: =_xlfn.XLOOKUP(ROW(O40)-ROW(O$28),報告用!$AO$4:$AO$39,報告用!$G$4:$G$39,"",FALSE) -> 小林 國光 | P40: =IF(O40="","","様") -> 様 | Q40: =IF(_xlfn.XLOOKUP(ROW(Q40)-ROW(Q$28),報告用!$AO$4:$AO$39,報告用!$E$4:$E$39,"",FALSE)=N40,"",_xlfn.XLOOKUP(ROW(Q40)-ROW(Q$28),報告用!$AO$4:$AO$39,報告用!$E$4:$E$39,"",FALSE)) -> 17
...

Sheet 報告用
G1: ★は土日も三食離床患者 | O1: ↓最終更新日はここに直接◯／□と入力するだけ
C2: 車いす | D2: 車いす | E2: 車いす | F2: 患者 | G2: 患者 | I2: 食事時 | J2: 午前・午後離床 | O2: 46106 | P2: 食事 | S2: 午前離床 | X2: 午後離床 | AC2: 食事順 | AF2: 午前離床順 | AK2: 午後離床順
B3: Gr | C3: No. | D3: タイプ | E3: 基地 | F3: 部屋 | G3: 氏名 | H3: 形態 | I3: パターン | J3: 月 | K3: 火 | L3: 水 | M3: 木 | N3: 金 | O3: 2 | P3: 三食 | Q3: 昼 | R3: 夜 | S3: 月am | T3: 火am | U3: 水am | V3: 木am | W3: 金am | X3: 月pm | Y3: 火pm | Z3: 水pm | AA3: 木pm | AB3: 金pm | AC3: 三食r | AD3: 昼r | AE3: 夜r | AF3: 月ra | AG3: 火ra | AH3: 水ra | AI3: 木ra | AJ3: 金ra | AK3: 月19 | AL3: 火20 | AM3: 水21 | AN3: 木22 | AO3: 金23
B4: A | C4: 1 | D4: KXL | E4: 15 | F4: 15 | G4: 佐藤 亜美 | H4: 共用 | I4: 毎日 | J4: PM | K4: PM | L4: PM | M4: PM | N4: PM | P4: =IF($I4=P$3,IF($F4>14,$F4/100,$F4),"") | Q4: =IF($I4=Q$3,IF($F4>14,$F4/100,$F4),"") | R4: =IF($I4=R$3,$F4,"") | S4: =IF(J4="AM",IF($F4>14,$F4/100,$F4),"") | T4: =IF(K4="AM",IF($F4>14,$F4/100,$F4),"") | U4: =IF(L4="AM",IF($F4>14,$F4/100,$F4),"") | V4: =IF(M4="AM",IF($F4>14,$F4/100,$F4),"") | W4: =IF(N4="AM",IF($F4>14,$F4/100,$F4),"") | X4: =IF(J4="PM",IF($F4>14,$F4/100,$F4),"") -> 0.15 | Y4: =IF(K4="PM",IF($F4>14,$F4/100,$F4),"") -> 0.15 | Z4: =IF(L4="PM",IF($F4>14,$F4/100,$F4),"") -> 0.15 | AA4: =IF(M4="PM",IF($F4>14,$F4/100,$F4),"") -> 0.15 | AB4: =IF(N4="PM",IF($F4>14,$F4/100,$F4),"") -> 0.15 | AC4: =IF(P4="","",_xlfn.RANK.EQ(P4,P$4:P$41,1)+COUNTIF(P4:P$41,P4)-1) | AD4: =IF(Q4="","",_xlfn.RANK.EQ(Q4,Q$4:Q$41,1)+COUNTIF(Q4:Q$41,Q4)-1) | AE4: =IF(R4="","",_xlfn.RANK.EQ(R4,R$4:R$41,1)+COUNTIF(R4:R$41,R4)-1) | AF4: =IF(S4="","",_xlfn.RANK.EQ(S4,S$4:S$39,1)+COUNTIF(S4:S$39,S4)-1) | AG4: =IF(T4="","",_xlfn.RANK.EQ(T4,T$4:T$39,1)+COUNTIF(T4:T$39,T4)-1) | AH4: =IF(U4="","",_xlfn.RANK.EQ(U4,U$4:U$39,1)+COUNTIF(U4:U$39,U4)-1) | AI4: =IF(V4="","",_xlfn.RANK.EQ(V4,V$4:V$39,1)+COUNTIF(V4:V$39,V4)-1) | AJ4: =IF(W4="","",_xlfn.RANK.EQ(W4,W$4:W$39,1)+COUNTIF(W4:W$39,W4)-1) | AK4: =IF(X4="","",_xlfn.RANK.EQ(X4,X$4:X$41,1)+COUNTIF(X4:X$41,X4)-1) -> 2 | AL4: =IF(Y4="","",_xlfn.RANK.EQ(Y4,Y$4:Y$41,1)+COUNTIF(Y4:Y$41,Y4)-1) -> 2 | AM4: =IF(Z4="","",_xlfn.RANK.EQ(Z4,Z$4:Z$41,1)+COUNTIF(Z4:Z$41,Z4)-1) -> 2 | AN4: =IF(AA4="","",_xlfn.RANK.EQ(AA4,AA$4:AA$41,1)+COUNTIF(AA4:AA$41,AA4)-1) -> 2 | AO4: =IF(AB4="","",_xlfn.RANK.EQ(AB4,AB$4:AB$41,1)+COUNTIF(AB4:AB$41,AB4)-1) -> 2
B5: A | C5: 1 | D5: KXL | E5: 15 | F5: 15 | G5: 望月 美希 | H5: 共用 | I5: 火金 | K5: AM | M5: AM | P5: =IF($I5=P$3,IF($F5>14,$F5/100,$F5),"") | Q5: =IF($I5=Q$3,IF($F5>14,$F5/100,$F5),"") | R5: =IF($I5=R$3,$F5,"") | S5: =IF(J5="AM",IF($F5>14,$F5/100,$F5),"") | T5: =IF(K5="AM",IF($F5>14,$F5/100,$F5),"") -> 0.15 | U5: =IF(L5="AM",IF($F5>14,$F5/100,$F5),"") | V5: =IF(M5="AM",IF($F5>14,$F5/100,$F5),"") -> 0.15 | W5: =IF(N5="AM",IF($F5>14,$F5/100,$F5),"") | X5: =IF(J5="PM",IF($F5>14,$F5/100,$F5),"") | Y5: =IF(K5="PM",IF($F5>14,$F5/100,$F5),"") | Z5: =IF(L5="PM",IF($F5>14,$F5/100,$F5),"") | AA5: =IF(M5="PM",IF($F5>14,$F5/100,$F5),"") | AB5: =IF(N5="PM",IF($F5>14,$F5/100,$F5),"") | AC5: =IF(P5="","",_xlfn.RANK.EQ(P5,P$4:P$41,1)+COUNTIF(P5:P$41,P5)-1) | AD5: =IF(Q5="","",_xlfn.RANK.EQ(Q5,Q$4:Q$41,1)+COUNTIF(Q5:Q$41,Q5)-1) | AE5: =IF(R5="","",_xlfn.RANK.EQ(R5,R$4:R$41,1)+COUNTIF(R5:R$41,R5)-1) | AF5: =IF(S5="","",_xlfn.RANK.EQ(S5,S$4:S$39,1)+COUNTIF(S5:S$39,S5)-1) | AG5: =IF(T5="","",_xlfn.RANK.EQ(T5,T$4:T$39,1)+COUNTIF(T5:T$39,T5)-1) -> 2 | AH5: =IF(U5="","",_xlfn.RANK.EQ(U5,U$4:U$39,1)+COUNTIF(U5:U$39,U5)-1) | AI5: =IF(V5="","",_xlfn.RANK.EQ(V5,V$4:V$39,1)+COUNTIF(V5:V$39,V5)-1) -> 2 | AJ5: =IF(W5="","",_xlfn.RANK.EQ(W5,W$4:W$39,1)+COUNTIF(W5:W$39,W5)-1) | AK5: =IF(X5="","",_xlfn.RANK.EQ(X5,X$4:X$41,1)+COUNTIF(X5:X$41,X5)-1) | AL5: =IF(Y5="","",_xlfn.RANK.EQ(Y5,Y$4:Y$41,1)+COUNTIF(Y5:Y$41,Y5)-1) | AM5: =IF(Z5="","",_xlfn.RANK.EQ(Z5,Z$4:Z$41,1)+COUNTIF(Z5:Z$41,Z5)-1) | AN5: =IF(AA5="","",_xlfn.RANK.EQ(AA5,AA$4:AA$41,1)+COUNTIF(AA5:AA$41,AA5)-1) | AO5: =IF(AB5="","",_xlfn.RANK.EQ(AB5,AB$4:AB$41,1)+COUNTIF(AB5:AB$41,AB5)-1)
B6: A | C6: 1 | D6: KXL | E6: 15 | F6: 15 | G6: 飯室 純江 | H6: 共用 | I6: 月水 | J6: AM | L6: AM | P6: =IF($I6=P$3,IF($F6>14,$F6/100,$F6),"") | Q6: =IF($I6=Q$3,IF($F6>14,$F6/100,$F6),"") | R6: =IF($I6=R$3,$F6,"") | S6: =IF(J6="AM",IF($F6>14,$F6/100,$F6),"") -> 0.15 | T6: =IF(K6="AM",IF($F6>14,$F6/100,$F6),"") | U6: =IF(L6="AM",IF($F6>14,$F6/100,$F6),"") -> 0.15 | V6: =IF(M6="AM",IF($F6>14,$F6/100,$F6),"") | W6: =IF(N6="AM",IF($F6>14,$F6/100,$F6),"") | X6: =IF(J6="PM",IF($F6>14,$F6/100,$F6),"") | Y6: =IF(K6="PM",IF($F6>14,$F6/100,$F6),"") | Z6: =IF(L6="PM",IF($F6>14,$F6/100,$F6),"") | AA6: =IF(M6="PM",IF($F6>14,$F6/100,$F6),"") | AB6: =IF(N6="PM",IF($F6>14,$F6/100,$F6),"") | AC6: =IF(P6="","",_xlfn.RANK.EQ(P6,P$4:P$41,1)+COUNTIF(P6:P$41,P6)-1) | AD6: =IF(Q6="","",_xlfn.RANK.EQ(Q6,Q$4:Q$41,1)+COUNTIF(Q6:Q$41,Q6)-1) | AE6: =IF(R6="","",_xlfn.RANK.EQ(R6,R$4:R$41,1)+COUNTIF(R6:R$41,R6)-1) | AF6: =IF(S6="","",_xlfn.RANK.EQ(S6,S$4:S$39,1)+COUNTIF(S6:S$39,S6)-1) -> 2 | AG6: =IF(T6="","",_xlfn.RANK.EQ(T6,T$4:T$39,1)+COUNTIF(T6:T$39,T6)-1) | AH6: =IF(U6="","",_xlfn.RANK.EQ(U6,U$4:U$39,1)+COUNTIF(U6:U$39,U6)-1) -> 2 | AI6: =IF(V6="","",_xlfn.RANK.EQ(V6,V$4:V$39,1)+COUNTIF(V6:V$39,V6)-1) | AJ6: =IF(W6="","",_xlfn.RANK.EQ(W6,W$4:W$39,1)+COUNTIF(W6:W$39,W6)-1) | AK6: =IF(X6="","",_xlfn.RANK.EQ(X6,X$4:X$41,1)+COUNTIF(X6:X$41,X6)-1) | AL6: =IF(Y6="","",_xlfn.RANK.EQ(Y6,Y$4:Y$41,1)+COUNTIF(Y6:Y$41,Y6)-1) | AM6: =IF(Z6="","",_xlfn.RANK.EQ(Z6,Z$4:Z$41,1)+COUNTIF(Z6:Z$41,Z6)-1) | AN6: =IF(AA6="","",_xlfn.RANK.EQ(AA6,AA$4:AA$41,1)+COUNTIF(AA6:AA$41,AA6)-1) | AO6: =IF(AB6="","",_xlfn.RANK.EQ(AB6,AB$4:AB$41,1)+COUNTIF(AB6:AB$41,AB6)-1)
B7: A | C7: 4 | D7: KXL | E7: 16 | F7: 21 | G7: 加納 鉄也 | H7: 共用 | I7: 毎日 | J7: PM | K7: PM | L7: PM | M7: PM | N7: PM | P7: =IF($I7=P$3,IF($F7>14,$F7/100,$F7),"") | Q7: =IF($I7=Q$3,IF($F7>14,$F7/100,$F7),"") | R7: =IF($I7=R$3,$F7,"") | S7: =IF(J7="AM",IF($F7>14,$F7/100,$F7),"") | T7: =IF(K7="AM",IF($F7>14,$F7/100,$F7),"") | U7: =IF(L7="AM",IF($F7>14,$F7/100,$F7),"") | V7: =IF(M7="AM",IF($F7>14,$F7/100,$F7),"") | W7: =IF(N7="AM",IF($F7>14,$F7/100,$F7),"") | X7: =IF(J7="PM",IF($F7>14,$F7/100,$F7),"") -> 0.21 | Y7: =IF(K7="PM",IF($F7>14,$F7/100,$F7),"") -> 0.21 | Z7: =IF(L7="PM",IF($F7>14,$F7/100,$F7),"") -> 0.21 | AA7: =IF(M7="PM",IF($F7>14,$F7/100,$F7),"") -> 0.21 | AB7: =IF(N7="PM",IF($F7>14,$F7/100,$F7),"") -> 0.21 | AC7: =IF(P7="","",_xlfn.RANK.EQ(P7,P$4:P$41,1)+COUNTIF(P7:P$41,P7)-1) | AD7: =IF(Q7="","",_xlfn.RANK.EQ(Q7,Q$4:Q$41,1)+COUNTIF(Q7:Q$41,Q7)-1) | AE7: =IF(R7="","",_xlfn.RANK.EQ(R7,R$4:R$41,1)+COUNTIF(R7:R$41,R7)-1) | AF7: =IF(S7="","",_xlfn.RANK.EQ(S7,S$4:S$39,1)+COUNTIF(S7:S$39,S7)-1) | AG7: =IF(T7="","",_xlfn.RANK.EQ(T7,T$4:T$39,1)+COUNTIF(T7:T$39,T7)-1) | AH7: =IF(U7="","",_xlfn.RANK.EQ(U7,U$4:U$39,1)+COUNTIF(U7:U$39,U7)-1) | AI7: =IF(V7="","",_xlfn.RANK.EQ(V7,V$4:V$39,1)+COUNTIF(V7:V$39,V7)-1) | AJ7: =IF(W7="","",_xlfn.RANK.EQ(W7,W$4:W$39,1)+COUNTIF(W7:W$39,W7)-1) | AK7: =IF(X7="","",_xlfn.RANK.EQ(X7,X$4:X$41,1)+COUNTIF(X7:X$41,X7)-1) -> 14 | AL7: =IF(Y7="","",_xlfn.RANK.EQ(Y7,Y$4:Y$41,1)+COUNTIF(Y7:Y$41,Y7)-1) -> 12 | AM7: =IF(Z7="","",_xlfn.RANK.EQ(Z7,Z$4:Z$41,1)+COUNTIF(Z7:Z$41,Z7)-1) -> 13 | AN7: =IF(AA7="","",_xlfn.RANK.EQ(AA7,AA$4:AA$41,1)+COUNTIF(AA7:AA$41,AA7)-1) -> 12 | AO7: =IF(AB7="","",_xlfn.RANK.EQ(AB7,AB$4:AB$41,1)+COUNTIF(AB7:AB$41,AB7)-1) -> 14
B8: A | C8: 4 | D8: KXL | E8: 16 | F8: 16 | G8: 森 たい子 | H8: 共用 | I8: 昼 | J8: 昼 | K8: 昼 | L8: 昼 | M8: 昼 | N8: 昼 | P8: =IF($I8=P$3,IF($F8>14,$F8/100,$F8),"") | Q8: =IF($I8=Q$3,IF($F8>14,$F8/100,$F8),"") -> 0.16 | R8: =IF($I8=R$3,$F8,"") | S8: =IF(J8="AM",IF($F8>14,$F8/100,$F8),"") | T8: =IF(K8="AM",IF($F8>14,$F8/100,$F8),"") | U8: =IF(L8="AM",IF($F8>14,$F8/100,$F8),"") | V8: =IF(M8="AM",IF($F8>14,$F8/100,$F8),"") | W8: =IF(N8="AM",IF($F8>14,$F8/100,$F8),"") | X8: =IF(J8="PM",IF($F8>14,$F8/100,$F8),"") | Y8: =IF(K8="PM",IF($F8>14,$F8/100,$F8),"") | Z8: =IF(L8="PM",IF($F8>14,$F8/100,$F8),"") | AA8: =IF(M8="PM",IF($F8>14,$F8/100,$F8),"") | AB8: =IF(N8="PM",IF($F8>14,$F8/100,$F8),"") | AC8: =IF(P8="","",_xlfn.RANK.EQ(P8,P$4:P$41,1)+COUNTIF(P8:P$41,P8)-1) | AD8: =IF(Q8="","",_xlfn.RANK.EQ(Q8,Q$4:Q$41,1)+COUNTIF(Q8:Q$41,Q8)-1) -> 2 | AE8: =IF(R8="","",_xlfn.RANK.EQ(R8,R$4:R$41,1)+COUNTIF(R8:R$41,R8)-1) | AF8: =IF(S8="","",_xlfn.RANK.EQ(S8,S$4:S$39,1)+COUNTIF(S8:S$39,S8)-1) | AG8: =IF(T8="","",_xlfn.RANK.EQ(T8,T$4:T$39,1)+COUNTIF(T8:T$39,T8)-1) | AH8: =IF(U8="","",_xlfn.RANK.EQ(U8,U$4:U$39,1)+COUNTIF(U8:U$39,U8)-1) | AI8: =IF(V8="","",_xlfn.RANK.EQ(V8,V$4:V$39,1)+COUNTIF(V8:V$39,V8)-1) | AJ8: =IF(W8="","",_xlfn.RANK.EQ(W8,W$4:W$39,1)+COUNTIF(W8:W$39,W8)-1) | AK8: =IF(X8="","",_xlfn.RANK.EQ(X8,X$4:X$41,1)+COUNTIF(X8:X$41,X8)-1) | AL8: =IF(Y8="","",_xlfn.RANK.EQ(Y8,Y$4:Y$41,1)+COUNTIF(Y8:Y$41,Y8)-1) | AM8: =IF(Z8="","",_xlfn.RANK.EQ(Z8,Z$4:Z$41,1)+COUNTIF(Z8:Z$41,Z8)-1) | AN8: =IF(AA8="","",_xlfn.RANK.EQ(AA8,AA$4:AA$41,1)+COUNTIF(AA8:AA$41,AA8)-1) | AO8: =IF(AB8="","",_xlfn.RANK.EQ(AB8,AB$4:AB$41,1)+COUNTIF(AB8:AB$41,AB8)-1)
B9: A | C9: 4 | D9: KXL | E9: 16 | F9: 16 | G9: 森 たい子 | H9: 共用 | I9: 毎日 | J9: AM | K9: AM | L9: AM | M9: AM | N9: AM | P9: =IF($I9=P$3,IF($F9>14,$F9/100,$F9),"") | Q9: =IF($I9=Q$3,IF($F9>14,$F9/100,$F9),"") | R9: =IF($I9=R$3,$F9,"") | S9: =IF(J9="AM",IF($F9>14,$F9/100,$F9),"") -> 0.16 | T9: =IF(K9="AM",IF($F9>14,$F9/100,$F9),"") -> 0.16 | U9: =IF(L9="AM",IF($F9>14,$F9/100,$F9),"") -> 0.16 | V9: =IF(M9="AM",IF($F9>14,$F9/100,$F9),"") -> 0.16 | W9: =IF(N9="AM",IF($F9>14,$F9/100,$F9),"") -> 0.16 | X9: =IF(J9="PM",IF($F9>14,$F9/100,$F9),"") | Y9: =IF(K9="PM",IF($F9>14,$F9/100,$F9),"") | Z9: =IF(L9="PM",IF($F9>14,$F9/100,$F9),"") | AA9: =IF(M9="PM",IF($F9>14,$F9/100,$F9),"") | AB9: =IF(N9="PM",IF($F9>14,$F9/100,$F9),"") | AC9: =IF(P9="","",_xlfn.RANK.EQ(P9,P$4:P$41,1)+COUNTIF(P9:P$41,P9)-1) | AD9: =IF(Q9="","",_xlfn.RANK.EQ(Q9,Q$4:Q$41,1)+COUNTIF(Q9:Q$41,Q9)-1) | AE9: =IF(R9="","",_xlfn.RANK.EQ(R9,R$4:R$41,1)+COUNTIF(R9:R$41,R9)-1) | AF9: =IF(S9="","",_xlfn.RANK.EQ(S9,S$4:S$39,1)+COUNTIF(S9:S$39,S9)-1) -> 4 | AG9: =IF(T9="","",_xlfn.RANK.EQ(T9,T$4:T$39,1)+COUNTIF(T9:T$39,T9)-1) -> 4 | AH9: =IF(U9="","",_xlfn.RANK.EQ(U9,U$4:U$39,1)+COUNTIF(U9:U$39,U9)-1) -> 4 | AI9: =IF(V9="","",_xlfn.RANK.EQ(V9,V$4:V$39,1)+COUNTIF(V9:V$39,V9)-1) -> 4 | AJ9: =IF(W9="","",_xlfn.RANK.EQ(W9,W$4:W$39,1)+COUNTIF(W9:W$39,W9)-1) -> 3 | AK9: =IF(X9="","",_xlfn.RANK.EQ(X9,X$4:X$41,1)+COUNTIF(X9:X$41,X9)-1) | AL9: =IF(Y9="","",_xlfn.RANK.EQ(Y9,Y$4:Y$41,1)+COUNTIF(Y9:Y$41,Y9)-1) | AM9: =IF(Z9="","",_xlfn.RANK.EQ(Z9,Z$4:Z$41,1)+COUNTIF(Z9:Z$41,Z9)-1) | AN9: =IF(AA9="","",_xlfn.RANK.EQ(AA9,AA$4:AA$41,1)+COUNTIF(AA9:AA$41,AA9)-1) | AO9: =IF(AB9="","",_xlfn.RANK.EQ(AB9,AB$4:AB$41,1)+COUNTIF(AB9:AB$41,AB9)-1)
B10: A | C10: 10 | D10: KXL | E10: 16 | F10: 16 | G10: 西山 望 | H10: 共用 | I10: 毎日 | J10: PM | K10: PM | L10: PM | M10: PM | N10: PM | P10: =IF($I10=P$3,IF($F10>14,$F10/100,$F10),"") | Q10: =IF($I10=Q$3,IF($F10>14,$F10/100,$F10),"") | R10: =IF($I10=R$3,$F10,"") | S10: =IF(J10="AM",IF($F10>14,$F10/100,$F10),"") | T10: =IF(K10="AM",IF($F10>14,$F10/100,$F10),"") | U10: =IF(L10="AM",IF($F10>14,$F10/100,$F10),"") | V10: =IF(M10="AM",IF($F10>14,$F10/100,$F10),"") | W10: =IF(N10="AM",IF($F10>14,$F10/100,$F10),"") | X10: =IF(J10="PM",IF($F10>14,$F10/100,$F10),"") -> 0.16 | Y10: =IF(K10="PM",IF($F10>14,$F10/100,$F10),"") -> 0.16 | Z10: =IF(L10="PM",IF($F10>14,$F10/100,$F10),"") -> 0.16 | AA10: =IF(M10="PM",IF($F10>14,$F10/100,$F10),"") -> 0.16 | AB10: =IF(N10="PM",IF($F10>14,$F10/100,$F10),"") -> 0.16 | AC10: =IF(P10="","",_xlfn.RANK.EQ(P10,P$4:P$41,1)+COUNTIF(P10:P$41,P10)-1) | AD10: =IF(Q10="","",_xlfn.RANK.EQ(Q10,Q$4:Q$41,1)+COUNTIF(Q10:Q$41,Q10)-1) | AE10: =IF(R10="","",_xlfn.RANK.EQ(R10,R$4:R$41,1)+COUNTIF(R10:R$41,R10)-1) | AF10: =IF(S10="","",_xlfn.RANK.EQ(S10,S$4:S$39,1)+COUNTIF(S10:S$39,S10)-1) | AG10: =IF(T10="","",_xlfn.RANK.EQ(T10,T$4:T$39,1)+COUNTIF(T10:T$39,T10)-1) | AH10: =IF(U10="","",_xlfn.RANK.EQ(U10,U$4:U$39,1)+COUNTIF(U10:U$39,U10)-1) | AI10: =IF(V10="","",_xlfn.RANK.EQ(V10,V$4:V$39,1)+COUNTIF(V10:V$39,V10)-1) | AJ10: =IF(W10="","",_xlfn.RANK.EQ(W10,W$4:W$39,1)+COUNTIF(W10:W$39,W10)-1) | AK10: =IF(X10="","",_xlfn.RANK.EQ(X10,X$4:X$41,1)+COUNTIF(X10:X$41,X10)-1) -> 5 | AL10: =IF(Y10="","",_xlfn.RANK.EQ(Y10,Y$4:Y$41,1)+COUNTIF(Y10:Y$41,Y10)-1) -> 4 | AM10: =IF(Z10="","",_xlfn.RANK.EQ(Z10,Z$4:Z$41,1)+COUNTIF(Z10:Z$41,Z10)-1) -> 5 | AN10: =IF(AA10="","",_xlfn.RANK.EQ(AA10,AA$4:AA$41,1)+COUNTIF(AA10:AA$41,AA10)-1) -> 4 | AO10: =IF(AB10="","",_xlfn.RANK.EQ(AB10,AB$4:AB$41,1)+COUNTIF(AB10:AB$41,AB10)-1) -> 5
B11: A | C11: 1 | D11: カワムラ | E11: 20 | F11: 20 | G11: ★上條 礼子 | H11: 専用 | I11: 三食 | J11: 三食 | K11: 三食 | L11: 三食 | M11: 三食 | N11: 三食 | O11: ロホ私物 | P11: =IF($I11=P$3,IF($F11>14,$F11/100,$F11),"") -> 0.2 | Q11: =IF($I11=Q$3,IF($F11>14,$F11/100,$F11),"") | R11: =IF($I11=R$3,$F11,"") | S11: =IF(J11="AM",IF($F11>14,$F11/100,$F11),"") | T11: =IF(K11="AM",IF($F11>14,$F11/100,$F11),"") | U11: =IF(L11="AM",IF($F11>14,$F11/100,$F11),"") | V11: =IF(M11="AM",IF($F11>14,$F11/100,$F11),"") | W11: =IF(N11="AM",IF($F11>14,$F11/100,$F11),"") | X11: =IF(J11="PM",IF($F11>14,$F11/100,$F11),"") | Y11: =IF(K11="PM",IF($F11>14,$F11/100,$F11),"") | Z11: =IF(L11="PM",IF($F11>14,$F11/100,$F11),"") | AA11: =IF(M11="PM",IF($F11>14,$F11/100,$F11),"") | AB11: =IF(N11="PM",IF($F11>14,$F11/100,$F11),"") | AC11: =IF(P11="","",_xlfn.RANK.EQ(P11,P$4:P$41,1)+COUNTIF(P11:P$41,P11)-1) -> 2 | AD11: =IF(Q11="","",_xlfn.RANK.EQ(Q11,Q$4:Q$41,1)+COUNTIF(Q11:Q$41,Q11)-1) | AE11: =IF(R11="","",_xlfn.RANK.EQ(R11,R$4:R$41,1)+COUNTIF(R11:R$41,R11)-1) | AF11: =IF(S11="","",_xlfn.RANK.EQ(S11,S$4:S$39,1)+COUNTIF(S11:S$39,S11)-1) | AG11: =IF(T11="","",_xlfn.RANK.EQ(T11,T$4:T$39,1)+COUNTIF(T11:T$39,T11)-1) | AH11: =IF(U11="","",_xlfn.RANK.EQ(U11,U$4:U$39,1)+COUNTIF(U11:U$39,U11)-1) | AI11: =IF(V11="","",_xlfn.RANK.EQ(V11,V$4:V$39,1)+COUNTIF(V11:V$39,V11)-1) | AJ11: =IF(W11="","",_xlfn.RANK.EQ(W11,W$4:W$39,1)+COUNTIF(W11:W$39,W11)-1) | AK11: =IF(X11="","",_xlfn.RANK.EQ(X11,X$4:X$41,1)+COUNTIF(X11:X$41,X11)-1) | AL11: =IF(Y11="","",_xlfn.RANK.EQ(Y11,Y$4:Y$41,1)+COUNTIF(Y11:Y$41,Y11)-1) | AM11: =IF(Z11="","",_xlfn.RANK.EQ(Z11,Z$4:Z$41,1)+COUNTIF(Z11:Z$41,Z11)-1) | AN11: =IF(AA11="","",_xlfn.RANK.EQ(AA11,AA$4:AA$41,1)+COUNTIF(AA11:AA$41,AA11)-1) | AO11: =IF(AB11="","",_xlfn.RANK.EQ(AB11,AB$4:AB$41,1)+COUNTIF(AB11:AB$41,AB11)-1)
B12: A | C12: 5 | D12: カワムラ | P12: =IF($I12=P$3,IF($F12>14,$F12/100,$F12),"") | Q12: =IF($I12=Q$3,IF($F12>14,$F12/100,$F12),"") | R12: =IF($I12=R$3,$F12,"") | S12: =IF(J12="AM",IF($F12>14,$F12/100,$F12),"") | T12: =IF(K12="AM",IF($F12>14,$F12/100,$F12),"") | U12: =IF(L12="AM",IF($F12>14,$F12/100,$F12),"") | V12: =IF(M12="AM",IF($F12>14,$F12/100,$F12),"") | W12: =IF(N12="AM",IF($F12>14,$F12/100,$F12),"") | X12: =IF(J12="PM",IF($F12>14,$F12/100,$F12),"") | Y12: =IF(K12="PM",IF($F12>14,$F12/100,$F12),"") | Z12: =IF(L12="PM",IF($F12>14,$F12/100,$F12),"") | AA12: =IF(M12="PM",IF($F12>14,$F12/100,$F12),"") | AB12: =IF(N12="PM",IF($F12>14,$F12/100,$F12),"") | AC12: =IF(P12="","",_xlfn.RANK.EQ(P12,P$4:P$41,1)+COUNTIF(P12:P$41,P12)-1) | AD12: =IF(Q12="","",_xlfn.RANK.EQ(Q12,Q$4:Q$41,1)+COUNTIF(Q12:Q$41,Q12)-1) | AE12: =IF(R12="","",_xlfn.RANK.EQ(R12,R$4:R$41,1)+COUNTIF(R12:R$41,R12)-1) | AF12: =IF(S12="","",_xlfn.RANK.EQ(S12,S$4:S$39,1)+COUNTIF(S12:S$39,S12)-1) | AG12: =IF(T12="","",_xlfn.RANK.EQ(T12,T$4:T$39,1)+COUNTIF(T12:T$39,T12)-1) | AH12: =IF(U12="","",_xlfn.RANK.EQ(U12,U$4:U$39,1)+COUNTIF(U12:U$39,U12)-1) | AI12: =IF(V12="","",_xlfn.RANK.EQ(V12,V$4:V$39,1)+COUNTIF(V12:V$39,V12)-1) | AJ12: =IF(W12="","",_xlfn.RANK.EQ(W12,W$4:W$39,1)+COUNTIF(W12:W$39,W12)-1) | AK12: =IF(X12="","",_xlfn.RANK.EQ(X12,X$4:X$41,1)+COUNTIF(X12:X$41,X12)-1) | AL12: =IF(Y12="","",_xlfn.RANK.EQ(Y12,Y$4:Y$41,1)+COUNTIF(Y12:Y$41,Y12)-1) | AM12: =IF(Z12="","",_xlfn.RANK.EQ(Z12,Z$4:Z$41,1)+COUNTIF(Z12:Z$41,Z12)-1) | AN12: =IF(AA12="","",_xlfn.RANK.EQ(AA12,AA$4:AA$41,1)+COUNTIF(AA12:AA$41,AA12)-1) | AO12: =IF(AB12="","",_xlfn.RANK.EQ(AB12,AB$4:AB$41,1)+COUNTIF(AB12:AB$41,AB12)-1)
B13: A | C13: 10 | D13: カワムラ | P13: =IF($I13=P$3,IF($F13>14,$F13/100,$F13),"") | Q13: =IF($I13=Q$3,IF($F13>14,$F13/100,$F13),"") | R13: =IF($I13=R$3,$F13,"") | S13: =IF(J13="AM",IF($F13>14,$F13/100,$F13),"") | T13: =IF(K13="AM",IF($F13>14,$F13/100,$F13),"") | U13: =IF(L13="AM",IF($F13>14,$F13/100,$F13),"") | V13: =IF(M13="AM",IF($F13>14,$F13/100,$F13),"") | W13: =IF(N13="AM",IF($F13>14,$F13/100,$F13),"") | X13: =IF(J13="PM",IF($F13>14,$F13/100,$F13),"") | Y13: =IF(K13="PM",IF($F13>14,$F13/100,$F13),"") | Z13: =IF(L13="PM",IF($F13>14,$F13/100,$F13),"") | AA13: =IF(M13="PM",IF($F13>14,$F13/100,$F13),"") | AB13: =IF(N13="PM",IF($F13>14,$F13/100,$F13),"") | AC13: =IF(P13="","",_xlfn.RANK.EQ(P13,P$4:P$41,1)+COUNTIF(P13:P$41,P13)-1) | AD13: =IF(Q13="","",_xlfn.RANK.EQ(Q13,Q$4:Q$41,1)+COUNTIF(Q13:Q$41,Q13)-1) | AE13: =IF(R13="","",_xlfn.RANK.EQ(R13,R$4:R$41,1)+COUNTIF(R13:R$41,R13)-1) | AF13: =IF(S13="","",_xlfn.RANK.EQ(S13,S$4:S$39,1)+COUNTIF(S13:S$39,S13)-1) | AG13: =IF(T13="","",_xlfn.RANK.EQ(T13,T$4:T$39,1)+COUNTIF(T13:T$39,T13)-1) | AH13: =IF(U13="","",_xlfn.RANK.EQ(U13,U$4:U$39,1)+COUNTIF(U13:U$39,U13)-1) | AI13: =IF(V13="","",_xlfn.RANK.EQ(V13,V$4:V$39,1)+COUNTIF(V13:V$39,V13)-1) | AJ13: =IF(W13="","",_xlfn.RANK.EQ(W13,W$4:W$39,1)+COUNTIF(W13:W$39,W13)-1) | AK13: =IF(X13="","",_xlfn.RANK.EQ(X13,X$4:X$41,1)+COUNTIF(X13:X$41,X13)-1) | AL13: =IF(Y13="","",_xlfn.RANK.EQ(Y13,Y$4:Y$41,1)+COUNTIF(Y13:Y$41,Y13)-1) | AM13: =IF(Z13="","",_xlfn.RANK.EQ(Z13,Z$4:Z$41,1)+COUNTIF(Z13:Z$41,Z13)-1) | AN13: =IF(AA13="","",_xlfn.RANK.EQ(AA13,AA$4:AA$41,1)+COUNTIF(AA13:AA$41,AA13)-1) | AO13: =IF(AB13="","",_xlfn.RANK.EQ(AB13,AB$4:AB$41,1)+COUNTIF(AB13:AB$41,AB13)-1)
B14: A | C14: 1 | D14: コンパクト | E14: 21 | F14: 21 | G14: 土田 茂 | H14: 共用 | I14: 昼 | J14: 昼 | K14: 昼 | L14: 昼 | M14: 昼 | N14: 昼 | P14: =IF($I14=P$3,IF($F14>14,$F14/100,$F14),"") | Q14: =IF($I14=Q$3,IF($F14>14,$F14/100,$F14),"") -> 0.21 | R14: =IF($I14=R$3,$F14,"") | S14: =IF(J14="AM",IF($F14>14,$F14/100,$F14),"") | T14: =IF(K14="AM",IF($F14>14,$F14/100,$F14),"") | U14: =IF(L14="AM",IF($F14>14,$F14/100,$F14),"") | V14: =IF(M14="AM",IF($F14>14,$F14/100,$F14),"") | W14: =IF(N14="AM",IF($F14>14,$F14/100,$F14),"") | X14: =IF(J14="PM",IF($F14>14,$F14/100,$F14),"") | Y14: =IF(K14="PM",IF($F14>14,$F14/100,$F14),"") | Z14: =IF(L14="PM",IF($F14>14,$F14/100,$F14),"") | AA14: =IF(M14="PM",IF($F14>14,$F14/100,$F14),"") | AB14: =IF(N14="PM",IF($F14>14,$F14/100,$F14),"") | AC14: =IF(P14="","",_xlfn.RANK.EQ(P14,P$4:P$41,1)+COUNTIF(P14:P$41,P14)-1) | AD14: =IF(Q14="","",_xlfn.RANK.EQ(Q14,Q$4:Q$41,1)+COUNTIF(Q14:Q$41,Q14)-1) -> 4 | AE14: =IF(R14="","",_xlfn.RANK.EQ(R14,R$4:R$41,1)+COUNTIF(R14:R$41,R14)-1) | AF14: =IF(S14="","",_xlfn.RANK.EQ(S14,S$4:S$39,1)+COUNTIF(S14:S$39,S14)-1) | AG14: =IF(T14="","",_xlfn.RANK.EQ(T14,T$4:T$39,1)+COUNTIF(T14:T$39,T14)-1) | AH14: =IF(U14="","",_xlfn.RANK.EQ(U14,U$4:U$39,1)+COUNTIF(U14:U$39,U14)-1) | AI14: =IF(V14="","",_xlfn.RANK.EQ(V14,V$4:V$39,1)+COUNTIF(V14:V$39,V14)-1) | AJ14: =IF(W14="","",_xlfn.RANK.EQ(W14,W$4:W$39,1)+COUNTIF(W14:W$39,W14)-1) | AK14: =IF(X14="","",_xlfn.RANK.EQ(X14,X$4:X$41,1)+COUNTIF(X14:X$41,X14)-1) | AL14: =IF(Y14="","",_xlfn.RANK.EQ(Y14,Y$4:Y$41,1)+COUNTIF(Y14:Y$41,Y14)-1) | AM14: =IF(Z14="","",_xlfn.RANK.EQ(Z14,Z$4:Z$41,1)+COUNTIF(Z14:Z$41,Z14)-1) | AN14: =IF(AA14="","",_xlfn.RANK.EQ(AA14,AA$4:AA$41,1)+COUNTIF(AA14:AA$41,AA14)-1) | AO14: =IF(AB14="","",_xlfn.RANK.EQ(AB14,AB$4:AB$41,1)+COUNTIF(AB14:AB$41,AB14)-1)
B15: A | C15: 1 | D15: コンパクト | E15: 21 | F15: 21 | G15: 土田 茂 | H15: 共用 | I15: 毎日 | J15: PM | K15: PM | L15: PM | M15: PM | N15: PM | P15: =IF($I15=P$3,IF($F15>14,$F15/100,$F15),"") | Q15: =IF($I15=Q$3,IF($F15>14,$F15/100,$F15),"") | R15: =IF($I15=R$3,$F15,"") | S15: =IF(J15="AM",IF($F15>14,$F15/100,$F15),"") | T15: =IF(K15="AM",IF($F15>14,$F15/100,$F15),"") | U15: =IF(L15="AM",IF($F15>14,$F15/100,$F15),"") | V15: =IF(M15="AM",IF($F15>14,$F15/100,$F15),"") | W15: =IF(N15="AM",IF($F15>14,$F15/100,$F15),"") | X15: =IF(J15="PM",IF($F15>14,$F15/100,$F15),"") -> 0.21 | Y15: =IF(K15="PM",IF($F15>14,$F15/100,$F15),"") -> 0.21 | Z15: =IF(L15="PM",IF($F15>14,$F15/100,$F15),"") -> 0.21 | AA15: =IF(M15="PM",IF($F15>14,$F15/100,$F15),"") -> 0.21 | AB15: =IF(N15="PM",IF($F15>14,$F15/100,$F15),"") -> 0.21 | AC15: =IF(P15="","",_xlfn.RANK.EQ(P15,P$4:P$41,1)+COUNTIF(P15:P$41,P15)-1) | AD15: =IF(Q15="","",_xlfn.RANK.EQ(Q15,Q$4:Q$41,1)+COUNTIF(Q15:Q$41,Q15)-1) | AE15: =IF(R15="","",_xlfn.RANK.EQ(R15,R$4:R$41,1)+COUNTIF(R15:R$41,R15)-1) | AF15: =IF(S15="","",_xlfn.RANK.EQ(S15,S$4:S$39,1)+COUNTIF(S15:S$39,S15)-1) | AG15: =IF(T15="","",_xlfn.RANK.EQ(T15,T$4:T$39,1)+COUNTIF(T15:T$39,T15)-1) | AH15: =IF(U15="","",_xlfn.RANK.EQ(U15,U$4:U$39,1)+COUNTIF(U15:U$39,U15)-1) | AI15: =IF(V15="","",_xlfn.RANK.EQ(V15,V$4:V$39,1)+COUNTIF(V15:V$39,V15)-1) | AJ15: =IF(W15="","",_xlfn.RANK.EQ(W15,W$4:W$39,1)+COUNTIF(W15:W$39,W15)-1) | AK15: =IF(X15="","",_xlfn.RANK.EQ(X15,X$4:X$41,1)+COUNTIF(X15:X$41,X15)-1) -> 13 | AL15: =IF(Y15="","",_xlfn.RANK.EQ(Y15,Y$4:Y$41,1)+COUNTIF(Y15:Y$41,Y15)-1) -> 11 | AM15: =IF(Z15="","",_xlfn.RANK.EQ(Z15,Z$4:Z$41,1)+COUNTIF(Z15:Z$41,Z15)-1) -> 12 | AN15: =IF(AA15="","",_xlfn.RANK.EQ(AA15,AA$4:AA$41,1)+COUNTIF(AA15:AA$41,AA15)-1) -> 11 | AO15: =IF(AB15="","",_xlfn.RANK.EQ(AB15,AB$4:AB$41,1)+COUNTIF(AB15:AB$41,AB15)-1) -> 13
